Workbook
Name Fruits: 'Data Validation'!$C$76:$C$84
Name Meats: 'Data Validation'!$D$76:$D$79
Name Vegetables: 'Data Validation'!$B$76:$B$84

Sheet Goal Seek
A2: Loan Amount | B2: 3000000
A3: Payment period | B3: 10
A4: Interest Rate | B4: 0.18181818
A5: Payment Amount | B5: =E18 -> 6000000
A7: Loan Schedule | B7: Loan Balance | C7: Interest | D7: Principal | E7: Total Payment | G7: Loan Schedule | H7: Loan Balance | I7: Interest | J7: Principal | K7: Total Payment
A8: Y1 | B8: =B2 -> 3000000 | C8: =B8*$B$4 -> 545454.55 | D8: =$B$8/10 -> 300000 | E8: =C8+D8 -> 845454.55 | G8: Y1 | H8: =B8 -> 3000000 | I8: =H8*B4 -> 545454.55 | J8: =$B$8/$B$3 -> 300000 | K8: =I8+J8 -> 845454.55
A9: Y2 | B9: =B8-D8 -> 2700000 | C9: =B9*$B$4 -> 490909.09 | D9: =$B$8/10 -> 300000 | E9: =C9+D9 -> 790909.09 | G9: Y2 | H9: =H8-J8 -> 2700000 | I9: =H9*B4 -> 490909.09 | J9: =$B$8/$B$3 -> 300000 | K9: =I9+J9 -> 790909.09
A10: Y3 | B10: =B9-D9 -> 2400000 | C10: =B10*$B$4 -> 436363.64 | D10: =$B$8/10 -> 300000 | E10: =C10+D10 -> 736363.64 | G10: Y3 | H10: =H9-J9 -> 2400000 | I10: =H10*B4 -> 436363.64 | J10: =$B$8/$B$3 -> 300000 | K10: =I10+J10 -> 736363.64
A11: Y4 | B11: =B10-D10 -> 2100000 | C11: =B11*$B$4 -> 381818.18 | D11: =$B$8/10 -> 300000 | E11: =C11+D11 -> 681818.18 | G11: Y4 | H11: =H10-J10 -> 2100000 | I11: =H11*B4 -> 381818.18 | J11: =$B$8/$B$3 -> 300000 | K11: =I11+J11 -> 681818.18
A12: Y5 | B12: =B11-D11 -> 1800000 | C12: =B12*$B$4 -> 327272.73 | D12: =$B$8/10 -> 300000 | E12: =C12+D12 -> 627272.73 | G12: Y5 | H12: =H11-J11 -> 1800000 | I12: =H12*B4 -> 327272.73 | J12: =$B$8/$B$3 -> 300000 | K12: =I12+J12 -> 627272.73
A13: Y6 | B13: =B12-D12 -> 1500000 | C13: =B13*$B$4 -> 272727.27 | D13: =$B$8/10 -> 300000 | E13: =C13+D13 -> 572727.27 | G13: Y6 | H13: =H12-J12 -> 1500000 | I13: =H13*B4 -> 272727.27 | J13: =$B$8/$B$3 -> 300000 | K13: =I13+J13 -> 572727.27
A14: Y7 | B14: =B13-D13 -> 1200000 | C14: =B14*$B$4 -> 218181.82 | D14: =$B$8/10 -> 300000 | E14: =C14+D14 -> 518181.82 | G14: Y7 | H14: =H13-J13 -> 1200000 | I14: =H14*B4 -> 218181.82 | J14: =$B$8/$B$3 -> 300000 | K14: =I14+J14 -> 518181.82
A15: Y8 | B15: =B14-D14 -> 900000 | C15: =B15*$B$4 -> 163636.36 | D15: =$B$8/10 -> 300000 | E15: =C15+D15 -> 463636.36 | G15: Y8 | H15: =H14-J14 -> 900000 | I15: =H15*B4 -> 163636.36 | J15: =$B$8/$B$3 -> 300000 | K15: =I15+J15 -> 463636.36
A16: Y9 | B16: =B15-D15 -> 600000 | C16: =B16*$B$4 -> 109090.91 | D16: =$B$8/10 -> 300000 | E16: =C16+D16 -> 409090.91 | G16: Y9 | H16: =H15-J15 -> 600000 | I16: =H16*B4 -> 109090.91 | J16: =$B$8/$B$3 -> 300000 | K16: =I16+J16 -> 409090.91
A17: Y10 | B17: =B16-D16 -> 300000 | C17: =B17*$B$4 -> 54545.455 | D17: =$B$8/10 -> 300000 | E17: =C17+D17 -> 354545.45 | G17: Y10 | H17: =H16-J16 -> 300000 | I17: =H17*B4 -> 54545.455 | J17: =$B$8/$B$3 -> 300000 | K17: =I17+J17 -> 354545.45
E18: =SUM(E8:E17) -> 6000000 | K18: =SUM(K8:K17) -> 6000000

Sheet Goal Seek 2
A1: Full Day Training
A3: Cost Item | B3: Amount | C3: Amount | F3: Gross Profit
A4: Hotel Conference Room | B4: 50000 | C4: 50000
A5: Feeding per participant | B5: 1200 | C5: 1200
A6: Training Material | B6: 3000 | C6: 3000
A7: Certificate | B7: 2000 | C7: 2000
A8: Prize for best participant | B8: 50000 | C8: 50000
A10: Analysis based on estimates | B10: Figure
A11: Number of participants | B11: 40 | C11: 43.859649
A12: Course Fee | B12: 20000 | C12: 20000
A13: Total Feeding cost | B13: =B11*B5 -> 48000 | C13: =C11*C5 -> 52631.579
A14: Conference Room cost | B14: =B4 -> 50000 | C14: =C4 -> 50000
A15: Training Materials cost | B15: =B6*B11 -> 120000 | C15: =C11*C6 -> 131578.95
A16: Certificate Costs | B16: =B7*B11 -> 80000 | C16: =C11*C7 -> 87719.298
A17: Prize Award cost | B17: =B8 -> 50000 | C17: =C8 -> 50000
A19: Total Revenue | B19: =B11*B12 -> 800000 | C19: =C11*C12 -> 877192.98
A20: Total Cost | B20: =SUM(B13:B17) -> 348000 | C20: =SUM(C13:C17) -> 371929.82
A21: TaxFee (5%) | B21: =B19*0.05 -> 40000 | C21: =C19*5% -> 43859.649
A22: Contigencies (7%) | B22: =B19*0.07 -> 56000 | C22: =C19*7% -> 61403.509
A23: Gross Profit | B23: =B19-SUM(B20:B22) -> 356000 | C23: =C19-SUM(C20:C22) -> 400000

Sheet Scenario Manager
A1: Full Day Training
A3: Cost Item | B3: Amount | F3: Gross Profit | G3: 1500000
A4: Hotel Conference Room | B4: 50000 | C4: 50000
A5: Feeding per participant | B5: 1200 | C5: 1200
A6: Training Material | B6: 3000 | C6: 3000
A7: Certificate | B7: 2000 | C7: 2000
A8: Prize for best participant | B8: 50000 | C8: 50000
A10: Analysis based on estimates
A11: Number of participants | B11: 40 | C11: 50
A12: Course Fee | B12: 20000 | C12: 22000
A13: Total Feeding cost | B13: =B11*B5 -> 48000 | C13: =C11*C5 -> 60000
A14: Conference Room cost | B14: =B4 -> 50000 | C14: =C4 -> 50000
A15: Training Materials cost | B15: =B11*B6 -> 120000 | C15: =C11*C6 -> 150000
A16: Certificate Costs | B16: =B11*B7 -> 80000 | C16: =C11*C7 -> 100000
A17: Prize Award cost | B17: =B8 -> 50000 | C17: =C8 -> 50000
A19: Total Revenue | B19: =B12*B11 -> 800000 | C19: =C12*C11 -> 1100000
A20: Total Cost | B20: =SUM(B13:B17) -> 348000 | C20: =SUM(C13:C17) -> 410000
A21: TaxFee (5%) | B21: =B19*5% -> 40000 | C21: =C19*5% -> 55000
A22: Contigencies (7%) | B22: =B19*7% -> 56000 | C22: =C19*7% -> 77000
A23: Gross Profit | B23: =B19-SUM(B20:B22) -> 356000 | C23: =C19-SUM(C20:C22) -> 558000

Sheet Scenario Summary
B2: Scenario Summary
D3: Current Values: | E3: Case1 | F3: case2 | G3: Case3
E4: Created by Muski on 08-01-2026 | F4: Created by Muski on 08-01-2026 | G4: Created by Muski on 08-01-2026
B5: Changing Cells:
C6: $C$11 | D6: 50 | E6: 40 | F6: 45 | G6: 50
C7: $C$12 | D7: 22000 | E7: 21000 | F7: 18000 | G7: 22000
B8: Result Cells:
C9: $C$23 | D9: 558000 | E9: 391200 | F9: 333800 | G9: 558000
B10: Notes: Current Values column represents values of changing cells at
B11: time Scenario Summary Report was created. Changing cells for each
B12: scenario are highlighted in gray.

Sheet Scenario Manager-2
C2: Scenario manager in excel is a part of three what-if-analysis tools . We can use it to see the impact of changing input values without changing the actual data.
D5: Worst case | E5: Most likely | F5: Best likely
D6: 0.02 | E6: 0.01 | F6: 0.06
D7: 0.03 | E7: 0.01 | F7: 0.06
D8: 0.05 | E8: 0.06 | F8: 0.01
C10: Qtr1 | D10: Qtr2 | E10: Qtr3 | F10: Qtr4 | G10: Annual | H10: Q to Q growth
B11: Sales | C11: 2490000 | D11: =C11+C11*$H$11 -> 2514900 | E11: =D11+D11*$H$11 -> 2540049 | F11: =E11+E11*$H$11 -> 2565449.5 | G11: =SUM(C11:F11) -> 10110398 | H11: 0.01
B12: COGS | C12: 1700000 | D12: =C12+C12*$H$12 -> 1717000 | E12: =D12+D12*$H$12 -> 1734170 | F12: =E12+E12*$H$12 -> 1751511.7 | G12: =SUM(C12:F12) -> 6902681.7 | H12: 0.01
B13: GP | C13: =C11-C12 -> 790000 | D13: =D11-D12 -> 797900 | E13: =E11-E12 -> 805879 | F13: =F11-F12 -> 813937.79 | G13: =SUM(C13:F13) -> 3207716.8
B14: Expenses | C14: 500000 | D14: =C14+C14*$H$14 -> 530000 | E14: =D14+D14*$H$14 -> 561800 | F14: =E14+E14*$H$14 -> 595508 | G14: =SUM(C14:F14) -> 2187308 | H14: 0.06
B15: Profit | C15: =C11-(C12+C14) -> 290000 | D15: =D11-(D12+D14) -> 267900 | E15: =E11-(E12+E14) -> 244079 | F15: =F11-(F12+F14) -> 218429.79 | G15: =SUM(C15:F15) -> 1020408.8

Sheet Data table 1 var
B1: Book Store
C3: Total Number Of Books | D3: % Sold For The Highest Price
C4: 100 | D4: 0.8
D6: Number of Books | E6: UnitProfit
C7: Highest Price | D7: =D4*C4 -> 80 | E7: 50
C8: Lower Price | D8: =C4-D7 -> 20 | E8: 20
D10: Total Profit | E10: =(D7*E7)+(D8*E8) -> 4400
C12: =E10 -> 4400
B13: 0.6 | C13: 3800
B14: 0.7 | C14: 4100
B15: 0.8 | C15: 4400
B16: 0.9 | C16: 4700
B17: 1 | C17: 5000

Sheet Data Table 2 var
B1: Book Store
C3: Total Number Of Books | D3: % Sold For The Highest Price
C4: 100 | D4: 0.7
D6: Number ofBooks | E6: UnitProfit
C7: HighestPrice | D7: =C4*D4 -> 70 | E7: 50
C8: Lower Price | D8: =C4-D7 -> 30 | E8: 20
D10: Total Profit | E10: =(D7*E7)+(D8*E8) -> 4100
B12: =E10 -> 4100 | C12: 50 | D12: 60 | E12: 70
B13: 0.6 | C13: 3800 | D13: 4400 | E13: 5000
B14: 0.7 | C14: 4100 | D14: 4800 | E14: 5500
B15: 0.8 | C15: 4400 | D15: 5200 | E15: 6000
B16: 0.9 | C16: 4700 | D16: 5600 | E16: 6500
B17: 1 | C17: 5000 | D17: 6000 | E17: 7000

Sheet Data Table-1 Var-Row
B2: Data tables are one of the existing parts of What-If analysis tools, which allow you to observe your result by experimenting it with different values of variables and to compare the outcomes stored by the data table.
B6: Loan Analysis | G6: Loan Amount
G7: 1500000 | H7: 2000000 | I7: 2500000 | J7: 3000000 | K7: 3500000 | L7: 4000000 | M7: 4500000 | N7: 5000000
B8: Interest Rate: | C8: 0.08 | F8: =C12 -> 28669.563 | G8: 14334.781 | H8: 19113.042 | I8: 23891.302 | J8: 28669.563 | K8: 33447.823 | L8: 38226.083 | M8: 43004.344 | N8: 47782.604
B9: Months of loan | C9: 180
B10: Loan Amount: | C10: 3000000
B11: Payments Due: | C11: 0
B12: Monthly Payment: | C12: =-PMT(C8/12,C9,C10,C11,0) -> 28669.563
B13: Total Payment: | C13: =C12*C9 -> 5160521.3
B14: Total Interest: | C14: =C13-C10 -> 2160521.3

Sheet Data Table-1 Var-Column
B2: Data tables are one of the existing parts of What-If analysis tools, which allow you to observe your result by experimenting it with different values of variables and to compare the outcomes stored by the data table.
B6: Loan Analysis | G6: Loan Amount
F7: =C12 -> 28669.563 | G7: 1500000 | H7: 2000000 | I7: 2500000 | J7: 3000000 | K7: 3500000 | L7: 4000000 | M7: 4500000 | N7: 5000000
B8: Interest Rate: | C8: 0.08 | E8: Rate of Interest | F8: 0.075 | G8: 13905.185 | H8: 18540.247 | I8: 23175.309 | J8: 27810.371 | K8: 32445.433 | L8: 37080.494 | M8: 41715.556 | N8: 46350.618
B9: Months of loan | C9: 180 | F9: 0.076 | G9: 13990.562 | H9: 18654.082 | I9: 23317.603 | J9: 27981.123 | K9: 32644.644 | L9: 37308.164 | M9: 41971.685 | N9: 46635.205
B10: Loan Amount: | C10: 3000000 | F10: 0.077 | G10: 14076.21 | H10: 18768.28 | I10: 23460.35 | J10: 28152.42 | K10: 32844.49 | L10: 37536.56 | M10: 42228.63 | N10: 46920.7
B11: Payments Due: | C11: 0 | F11: 0.078 | G11: 14162.13 | H11: 18882.84 | I11: 23603.55 | J11: 28324.26 | K11: 33044.971 | L11: 37765.681 | M11: 42486.391 | N11: 47207.101
B12: Monthly Payment: | C12: =-PMT(C8/12,C9,C10,C11,0) -> 28669.563 | F12: 0.079 | G12: 14248.321 | H12: 18997.761 | I12: 23747.202 | J12: 28496.642 | K12: 33246.082 | L12: 37995.523 | M12: 42744.963 | N12: 47494.403
B13: Total Payment: | C13: =C12*C9 -> 5160521.3 | F13: 0.08 | G13: 14334.781 | H13: 19113.042 | I13: 23891.302 | J13: 28669.563 | K13: 33447.823 | L13: 38226.083 | M13: 43004.344 | N13: 47782.604
B14: Total Interest: | C14: =C13-C10 -> 2160521.3 | F14: 0.081 | G14: 14421.51 | H14: 19228.68 | I14: 24035.85 | J14: 28843.021 | K14: 33650.191 | L14: 38457.361 | M14: 43264.531 | N14: 48071.701
F15: 0.082 | G15: 14508.507 | H15: 19344.676 | I15: 24180.845 | J15: 29017.014 | K15: 33853.183 | L15: 38689.352 | M15: 43525.521 | N15: 48361.69
F16: 0.083 | G16: 14595.77 | H16: 19461.027 | I16: 24326.284 | J16: 29191.541 | K16: 34056.797 | L16: 38922.054 | M16: 43787.311 | N16: 48652.568
F17: 0.084 | G17: 14683.299 | H17: 19577.733 | I17: 24472.166 | J17: 29366.599 | K17: 34261.032 | L17: 39155.465 | M17: 44049.898 | N17: 48944.332
F18: 0.085 | G18: 14771.093 | H18: 19694.791 | I18: 24618.489 | J18: 29542.187 | K18: 34465.885 | L18: 39389.582 | M18: 44313.28 | N18: 49236.978
F19: 0.086 | G19: 14859.151 | H19: 19812.201 | I19: 24765.252 | J19: 29718.302 | K19: 34671.352 | L19: 39624.403 | M19: 44577.453 | N19: 49530.503
F20: 0.087 | G20: 14947.471 | H20: 19929.962 | I20: 24912.452 | J20: 29894.943 | K20: 34877.433 | L20: 39859.924 | M20: 44842.414 | N20: 49824.905
F21: 0.088 | G21: 15036.053 | H21: 20048.071 | I21: 25060.089 | J21: 30072.107 | K21: 35084.125 | L21: 40096.143 | M21: 45108.16 | N21: 50120.178
F22: 0.089 | G22: 15124.896 | H22: 20166.528 | I22: 25208.16 | J22: 30249.793 | K22: 35291.425 | L22: 40333.057 | M22: 45374.689 | N22: 50416.321
F23: 0.09 | G23: 15213.999 | H23: 20285.332 | I23: 25356.665 | J23: 30427.998 | K23: 35499.33 | L23: 40570.663 | M23: 45641.996 | N23: 50713.329

Sheet Data Table 2
B2: Data tables are one of the existing parts of What-If analysis tools, which allow you to observe your result by experimenting it with different values of variables and to compare the outcomes stored by the data table.
B6: Loan Analysis | G6: Loan Amount
F7: =C12 -> 0 | G7: 1500000 | H7: 2000000 | I7: 2500000 | J7: 3000000 | K7: 3500000 | L7: 4000000 | M7: 4500000 | N7: 5000000
B8: Interest Rate: | C8: 0.08 | E8: Rate of Interest | F8: 0.075
B9: Months of loan | C9: 180 | F9: 0.076
B10: Loan Amount: | C10: 3000000 | F10: 0.077
B11: Payments Due: | C11: 0 | F11: 0.078
B12: Monthly Payment: | F12: 0.079
B13: Total Payment: | F13: 0.08
B14: Total Interest: | F14: 0.081
F15: 0.082
F16: 0.083
F17: 0.084
F18: 0.085
F19: 0.086
F20: 0.087
F21: 0.088
F22: 0.089
F23: 0.09

Sheet Solver
B2: Use Solver to find an optimal (maximum or minimum) value for a formula in one cell — called the objective cell — subject to constraints, or limits, on the values of other formula cells on a worksheet.
B12: Cost of Shipping Per Product
C13: Customer 1 | D13: Customer 2 | E13: Customer 3 | F13: Customer 4
B14: WareHouse1 | C14: 50 | D14: 65 | E14: 50 | F14: 90
B15: WareHouse2 | C15: 55 | D15: 70 | E15: 80 | F15: 75
B17: Number of Product Shipped
C18: Customer 1 | D18: Customer 2 | E18: Customer 3 | F18: Customer 4 | H18: Total Shipped | J18: Available in Warehouse
B19: WareHouse1 | C19: 32000 | D19: 0 | E19: 18000 | F19: 0 | H19: =SUM(C19:F19) -> 50000 | J19: 50000
B20: WareHouse2 | C20: 3000 | D20: 21000 | E20: 0 | F20: 33000 | H20: =SUM(C20:F20) -> 57000 | J20: 60000
B22: Total Received | C22: =SUM(C19:C20) -> 35000 | D22: =SUM(D19:D20) -> 21000 | E22: =SUM(E19:E20) -> 18000 | F22: =SUM(F19:F20) -> 33000
B23: Ordered | C23: 35000 | D23: 21000 | E23: 18000 | F23: 33000
B25: Total Shipping Cost | C25: =SUMPRODUCT(C14:F15,C19:F20) -> 6610000

Sheet Jan
A1: January Report
A3: Average of Monthly Gross Salary | B3: Mumbai | C3: Delhi | D3: Pune | E3: Nagpur | F3: Chennai | G3: Banglore
A4: Accounting | B4: 44000 | C4: 63014.667 | D4: 96110 | E4: 55828.667 | F4: 53278 | G4: 53274.333
A5: Business Development | B5: 71580.833 | C5: 53301.667 | D5: 76768.5 | E5: 68316.5 | F5: 64912.333 | G5: 101738.5
A6: Engineering | B6: 68228.8 | C6: 71992.25 | D6: 46774.667 | E6: 57441.667 | F6: 89982.167 | G6: 111181
A7: Human Resources | B7: 99555 | C7: 38930 | D7: 125835.29 | E7: 68348.714 | F7: 68549.714 | G7: 65911.333
A8: Legal | B8: 61826.8 | C8: 46426.25 | D8: 64245.25 | E8: 75779.5 | F8: 51527.75 | G8: 40834
A9: Marketing | B9: 123014.33 | C9: 43640.5 | D9: 48339.333 | E9: 53284.4 | F9: 69791.333 | G9: 152670.67
A10: Product Management | B10: 75382 | C10: 105891.14 | D10: 70183.75 | E10: 78184.333 | F10: 76775.8 | G10: 81244
A11: Research and Development | B11: 90331.6 | C11: 76744.333 | D11: 53212 | E11: 91280.333 | F11: 53268.5 | G11: 45260.25
A12: Sales | B12: 0 | C12: 72077.6 | D12: 53234.333 | E12: 116768.83 | F12: 38789.75 | G12: 71033.375
A13: Services | B13: 90042.2 | C13: 87655.2 | D13: 48094.167 | E13: 128191 | F13: 61102 | G13: 53291.5
A14: Support | B14: 142241.33 | C14: 67467 | D14: 53213.5 | E14: 118827.8 | F14: 121036 | G14: 54330.6
A15: Training | B15: 157682 | C15: 44431.8 | D15: 97265.5 | E15: 88315.429 | F15: 42113.333 | G15: 56045.8
A16: Grand Total | B16: =SUM(B4:B15) -> 1023884.9 | C16: =SUM(C4:C15) -> 771572.41 | D16: =SUM(D4:D15) -> 833276.29 | E16: =SUM(E4:E15) -> 1000567.2 | F16: =SUM(F4:F15) -> 791126.68 | G16: =SUM(G4:G15) -> 886815.36

Sheet Feb
A1: February Report
A3: Average of Monthly Gross Salary | B3: Mumbai | C3: Delhi | D3: Pune | E3: Nagpur | F3: Chennai | G3: Kota
A4: Sales | B4: 48968 | C4: 72077.6 | D4: 53234.333 | E4: 116768.83 | F4: 38789.75 | G4: 71033.375
A5: Accounting | B5: 53247 | C5: 63014.667 | D5: 96110 | E5: 55828.667 | F5: 53278 | G5: 53274.333
A6: Legal | B6: 61826.8 | C6: 46426.25 | D6: 64245.25 | E6: 75779.5 | F6: 51527.75 | G6: 40834
A7: Engineering | B7: 68228.8 | C7: 71992.25 | D7: 46774.667 | E7: 57441.667 | F7: 89982.167 | G7: 111181
A8: Business Development | B8: 71580.833 | C8: 53301.667 | D8: 76768.5 | E8: 68316.5 | F8: 64912.333 | G8: 101738.5
A9: Product Management | B9: 75382 | C9: 105891.14 | D9: 70183.75 | E9: 78184.333 | F9: 76775.8 | G9: 81244
A10: Services | B10: 90042.2 | C10: 87655.2 | D10: 48094.167 | E10: 128191 | F10: 61102 | G10: 53291.5
A11: Research and Development | B11: 90331.6 | C11: 76744.333 | D11: 53212 | E11: 91280.333 | F11: 53268.5 | G11: 45260.25
A12: Human Resources | B12: 99555 | C12: 38930 | D12: 125835.29 | E12: 68348.714 | F12: 68549.714 | G12: 65911.333
A13: Marketing | B13: 123014.33 | C13: 43640.5 | D13: 48339.333 | E13: 53284.4 | F13: 69791.333 | G13: 152670.67
A14: Support | B14: 142241.33 | C14: 67467 | D14: 53213.5 | E14: 118827.8 | F14: 121036 | G14: 54330.6
A15: Training | B15: 157682 | C15: 44431.8 | D15: 97265.5 | E15: 88315.429 | F15: 42113.333 | G15: 56045.8
A16: Grand Total | B16: =SUM(B4:B15) -> 1082099.9 | C16: =SUM(C4:C15) -> 771572.41 | D16: =SUM(D4:D15) -> 833276.29 | E16: =SUM(E4:E15) -> 1000567.2 | F16: =SUM(F4:F15) -> 791126.68 | G16: =SUM(G4:G15) -> 886815.36

Sheet Mar
A1: March Report
A3: Average of Monthly Gross Salary | B3: Hydrabad | C3: Delhi | D3: Pune | E3: Nagpur | F3: Chennai | G3: Banglore
A4: Marketing | B4: 123014.33 | C4: 43640.5 | D4: 48339.333 | E4: 53284.4 | F4: 69791.333 | G4: 152670.67
A5: Accounting | B5: 53247 | C5: 63014.667 | D5: 96110 | E5: 55828.667 | F5: 53278 | G5: 53274.333
A6: Engineering | B6: 68228.8 | C6: 71992.25 | D6: 46774.667 | E6: 57441.667 | F6: 89982.167 | G6: 111181
A7: Business Development | B7: 71580.833 | C7: 53301.667 | D7: 76768.5 | E7: 68316.5 | F7: 64912.333 | G7: 101738.5
A8: Human Resources | B8: 99555 | C8: 38930 | D8: 125835.29 | E8: 68348.714 | F8: 68549.714 | G8: 65911.333
A9: Legal | B9: 61826.8 | C9: 46426.25 | D9: 64245.25 | E9: 75779.5 | F9: 51527.75 | G9: 40834
A10: Product Management | B10: 75382 | C10: 105891.14 | D10: 70183.75 | E10: 78184.333 | F10: 76775.8 | G10: 81244
A11: Training | B11: 157682 | C11: 44431.8 | D11: 97265.5 | E11: 88315.429 | F11: 42113.333 | G11: 56045.8
A12: Research and Development | B12: 90331.6 | C12: 76744.333 | D12: 53212 | E12: 91280.333 | F12: 53268.5 | G12: 45260.25
A13: Sales | B13: 48968 | C13: 72077.6 | D13: 53234.333 | E13: 116768.83 | F13: 38789.75 | G13: 71033.375
A14: Services | B14: 90042.2 | C14: 87655.2 | D14: 48094.167 | E14: 128191 | F14: 61102 | G14: 53291.5
A15: Grand Total | B15: =SUM(B4:B14) -> 939858.57 | C15: =SUM(C4:C14) -> 704105.41 | D15: =SUM(D4:D14) -> 780062.79 | E15: =SUM(E4:E14) -> 881739.38 | F15: =SUM(F4:F14) -> 670090.68 | G15: =SUM(G4:G14) -> 832484.76

Sheet Expected Report
A1: Qrt1 Report
A3: Average of Monthly Gross Salary | D3: Mumbai | E3: Hydrabad | F3: Delhi | G3: Pune | H3: Nagpur | I3: Chennai | J3: Kota | K3: Banglore
A4: Sales | D4: 97936 | E4: 48968 | F4: 216232.8 | G4: 159703 | H4: 350306.5 | I4: 116369.25 | J4: 71033.375 | K4: 142066.75
A5: Accounting | D5: 106494 | E5: 53247 | F5: 189044 | G5: 288330 | H5: 167486 | I5: 159834 | J5: 53274.333 | K5: 106548.67
A6: Legal | D6: 123653.6 | E6: 61826.8 | F6: 139278.75 | G6: 192735.75 | H6: 227338.5 | I6: 154583.25 | J6: 40834 | K6: 81668
A7: Engineering | D7: 136457.6 | E7: 68228.8 | F7: 215976.75 | G7: 140324 | H7: 172325 | I7: 269946.5 | J7: 111181 | K7: 222362
A8: Business Development | D8: 143161.67 | E8: 71580.833 | F8: 159905 | G8: 230305.5 | H8: 204949.5 | I8: 194737 | J8: 101738.5 | K8: 203477
A9: Product Management | D9: 150764 | E9: 75382 | F9: 317673.43 | G9: 210551.25 | H9: 234553 | I9: 230327.4 | J9: 81244 | K9: 162488
A10: Services | D10: 180084.4 | E10: 90042.2 | F10: 262965.6 | G10: 144282.5 | H10: 384573 | I10: 183306 | J10: 53291.5 | K10: 106583
A11: Research and Development | D11: 180663.2 | E11: 90331.6 | F11: 230233 | G11: 159636 | H11: 273841 | I11: 159805.5 | J11: 45260.25 | K11: 90520.5
A12: Human Resources | D12: 199110 | E12: 99555 | F12: 116790 | G12: 377505.86 | H12: 205046.14 | I12: 205649.14 | J12: 65911.333 | K12: 131822.67
A13: Marketing | D13: 246028.67 | E13: 123014.33 | F13: 130921.5 | G13: 145018 | H13: 159853.2 | I13: 209374 | J13: 152670.67 | K13: 305341.33
A14: Support | D14: 284482.67 | F14: 134934 | G14: 106427 | H14: 237655.6 | I14: 242072 | J14: 54330.6 | K14: 54330.6
A15: Training | D15: 315364 | E15: 157682 | F15: 133295.4 | G15: 291796.5 | H15: 264946.29 | I15: 126340 | J15: 56045.8 | K15: 112091.6
A16: Grand Total | D16: 2164199.8 | E16: 939858.57 | F16: 2247250.2 | G16: 2446615.4 | H16: 2882873.7 | I16: 2252344 | J16: 886815.36 | K16: 1719300.1
A19: Average of Monthly Gross Salary | C19: Mumbai | D19: Hydrabad | E19: Delhi | F19: Pune | G19: Nagpur | H19: Chennai | I19: Kota | J19: Banglore
C20: =Feb!$B$4 -> 48968 | E20: =Feb!$C$4 -> 72077.6 | F20: =Feb!$D$4 -> 53234.333 | G20: =Feb!$E$4 -> 116768.83 | H20: =Feb!$F$4 -> 38789.75 | I20: =Feb!$G$4 -> 71033.375
C21: =Jan!$B$12 -> 0 | E21: =Jan!$C$12 -> 72077.6 | F21: =Jan!$D$12 -> 53234.333 | G21: =Jan!$E$12 -> 116768.83 | H21: =Jan!$F$12 -> 38789.75 | J21: =Jan!$G$12 -> 71033.375
D22: =Mar!$B$13 -> 48968 | E22: =Mar!$C$13 -> 72077.6 | F22: =Mar!$D$13 -> 53234.333 | G22: =Mar!$E$13 -> 116768.83 | H22: =Mar!$F$13 -> 38789.75 | J22: =Mar!$G$13 -> 71033.375
A23: Sales | C23: =SUM(C20:C22) -> 48968 | D23: =SUM(D20:D22) -> 48968 | E23: =SUM(E20:E22) -> 216232.8 | F23: =SUM(F20:F22) -> 159703 | G23: =SUM(G20:G22) -> 350306.5 | H23: =SUM(H20:H22) -> 116369.25 | I23: =SUM(I20:I22) -> 71033.375 | J23: =SUM(J20:J22) -> 142066.75
C24: =Feb!$B$5 -> 53247 | E24: =Feb!$C$5 -> 63014.667 | F24: =Feb!$D$5 -> 96110 | G24: =Feb!$E$5 -> 55828.667 | H24: =Feb!$F$5 -> 53278 | I24: =Feb!$G$5 -> 53274.333
C25: =Jan!$B$4 -> 44000 | E25: =Jan!$C$4 -> 63014.667 | F25: =Jan!$D$4 -> 96110 | G25: =Jan!$E$4 -> 55828.667 | H25: =Jan!$F$4 -> 53278 | J25: =Jan!$G$4 -> 53274.333
D26: =Mar!$B$5 -> 53247 | E26: =Mar!$C$5 -> 63014.667 | F26: =Mar!$D$5 -> 96110 | G26: =Mar!$E$5 -> 55828.667 | H26: =Mar!$F$5 -> 53278 | J26: =Mar!$G$5 -> 53274.333
A27: Accounting | C27: =SUM(C24:C26) -> 97247 | D27: =SUM(D24:D26) -> 53247 | E27: =SUM(E24:E26) -> 189044 | F27: =SUM(F24:F26) -> 288330 | G27: =SUM(G24:G26) -> 167486 | H27: =SUM(H24:H26) -> 159834 | I27: =SUM(I24:I26) -> 53274.333 | J27: =SUM(J24:J26) -> 106548.67
C28: =Feb!$B$6 -> 61826.8 | E28: =Feb!$C$6 -> 46426.25 | F28: =Feb!$D$6 -> 64245.25 | G28: =Feb!$E$6 -> 75779.5 | H28: =Feb!$F$6 -> 51527.75 | I28: =Feb!$G$6 -> 40834
C29: =Jan!$B$8 -> 61826.8 | E29: =Jan!$C$8 -> 46426.25 | F29: =Jan!$D$8 -> 64245.25 | G29: =Jan!$E$8 -> 75779.5 | H29: =Jan!$F$8 -> 51527.75 | J29: =Jan!$G$8 -> 40834
D30: =Mar!$B$9 -> 61826.8 | E30: =Mar!$C$9 -> 46426.25 | F30: =Mar!$D$9 -> 64245.25 | G30: =Mar!$E$9 -> 75779.5 | H30: =Mar!$F$9 -> 51527.75 | J30: =Mar!$G$9 -> 40834
A31: Legal | C31: =SUM(C28:C30) -> 123653.6 | D31: =SUM(D28:D30) -> 61826.8 | E31: =SUM(E28:E30) -> 139278.75 | F31: =SUM(F28:F30) -> 192735.75 | G31: =SUM(G28:G30) -> 227338.5 | H31: =SUM(H28:H30) -> 154583.25 | I31: =SUM(I28:I30) -> 40834 | J31: =SUM(J28:J30) -> 81668
C32: =Feb!$B$7 -> 68228.8 | E32: =Feb!$C$7 -> 71992.25 | F32: =Feb!$D$7 -> 46774.667 | G32: =Feb!$E$7 -> 57441.667 | H32: =Feb!$F$7 -> 89982.167 | I32: =Feb!$G$7 -> 111181
C33: =Jan!$B$6 -> 68228.8 | E33: =Jan!$C$6 -> 71992.25 | F33: =Jan!$D$6 -> 46774.667 | G33: =Jan!$E$6 -> 57441.667 | H33: =Jan!$F$6 -> 89982.167 | J33: =Jan!$G$6 -> 111181
D34: =Mar!$B$6 -> 68228.8 | E34: =Mar!$C$6 -> 71992.25 | F34: =Mar!$D$6 -> 46774.667 | G34: =Mar!$E$6 -> 57441.667 | H34: =Mar!$F$6 -> 89982.167 | J34: =Mar!$G$6 -> 111181
A35: Engineering | C35: =SUM(C32:C34) -> 136457.6 | D35: =SUM(D32:D34) -> 68228.8 | E35: =SUM(E32:E34) -> 215976.75 | F35: =SUM(F32:F34) -> 140324 | G35: =SUM(G32:G34) -> 172325 | H35: =SUM(H32:H34) -> 269946.5 | I35: =SUM(I32:I34) -> 111181 | J35: =SUM(J32:J34) -> 222362
C36: =Feb!$B$8 -> 71580.833 | E36: =Feb!$C$8 -> 53301.667 | F36: =Feb!$D$8 -> 76768.5 | G36: =Feb!$E$8 -> 68316.5 | H36: =Feb!$F$8 -> 64912.333 | I36: =Feb!$G$8 -> 101738.5
C37: =Jan!$B$5 -> 71580.833 | E37: =Jan!$C$5 -> 53301.667 | F37: =Jan!$D$5 -> 76768.5 | G37: =Jan!$E$5 -> 68316.5 | H37: =Jan!$F$5 -> 64912.333 | J37: =Jan!$G$5 -> 101738.5
D38: =Mar!$B$7 -> 71580.833 | E38: =Mar!$C$7 -> 53301.667 | F38: =Mar!$D$7 -> 76768.5 | G38: =Mar!$E$7 -> 68316.5 | H38: =Mar!$F$7 -> 64912.333 | J38: =Mar!$G$7 -> 101738.5
A39: Business Development | C39: =SUM(C36:C38) -> 143161.67 | D39: =SUM(D36:D38) -> 71580.833 | E39: =SUM(E36:E38) -> 159905 | F39: =SUM(F36:F38) -> 230305.5 | G39: =SUM(G36:G38) -> 204949.5 | H39: =SUM(H36:H38) -> 194737 | I39: =SUM(I36:I38) -> 101738.5 | J39: =SUM(J36:J38) -> 203477
C40: =Feb!$B$9 -> 75382 | E40: =Feb!$C$9 -> 105891.14 | F40: =Feb!$D$9 -> 70183.75 | G40: =Feb!$E$9 -> 78184.333 | H40: =Feb!$F$9 -> 76775.8 | I40: =Feb!$G$9 -> 81244
C41: =Jan!$B$10 -> 75382 | E41: =Jan!$C$10 -> 105891.14 | F41: =Jan!$D$10 -> 70183.75 | G41: =Jan!$E$10 -> 78184.333 | H41: =Jan!$F$10 -> 76775.8 | J41: =Jan!$G$10 -> 81244
D42: =Mar!$B$10 -> 75382 | E42: =Mar!$C$10 -> 105891.14 | F42: =Mar!$D$10 -> 70183.75 | G42: =Mar!$E$10 -> 78184.333 | H42: =Mar!$F$10 -> 76775.8 | J42: =Mar!$G$10 -> 81244
A43: Product Management | C43: =SUM(C40:C42) -> 150764 | D43: =SUM(D40:D42) -> 75382 | E43: =SUM(E40:E42) -> 317673.43 | F43: =SUM(F40:F42) -> 210551.25 | G43: =SUM(G40:G42) -> 234553 | H43: =SUM(H40:H42) -> 230327.4 | I43: =SUM(I40:I42) -> 81244 | J43: =SUM(J40:J42) -> 162488
...

Sheet Data Validation
A1: Ex.1 | B1: Allow any whole number between 0 to 100
B3: 3
B4: 0
B5: 100
A7: Ex.2 | B7: Allow any value between 0 to 100 with decimals
B9: 0.5
B10: 15
B11: 12
A13: Ex.3 | B13: Allow any value between 0 to 100 with input message as "Please Enter any value between 0 to 100"
B15: 100
B16: 0.556
B17: 11.789
A19: Ex.4 | B19: Error Alert
B20: Enter any whole number between 0 to 100
B22: 0
B23: 100
B24: 20
A26: Ex.5 | B26: Create a list from range E28:E29
B28: Student | C28: Attendance | E28: Yes | F28: Data validation list
B29: Gitesh | C29: Yes | E29: No
B30: Mahesh | C30: No
B31: Melvin | C31: Yes
B32: Neelesh | C32: Yes
B33: Kishor | C33: No
B34: Ashish | C34: No
A37: Ex.6 | B37: Create a validation list so that user can only enter dates between 1st Apr 2019 and 31st Mar.2020
B39: 43586
B40: 43742 | C40: 43791 | D40: 43852
B41: 43921
A45: Ex.7 | B45: Validate cell show that the duplicate values are not allowed
B46: 1 | C46: Muskan | D46: Roshni
B47: 2 | C47: 13 | D47: Kanchan
B48: 3 | C48: 31 | D48: Deepak
A50: Ex.8 | B50: Validate cells so that first three characters are "EMP"
B52: emp123 | C52: =LEFT(B52,3)="EMP" -> TRUE | D52: =LEN(B52)=6 -> TRUE | E52: =AND(LEFT(B52,3)="EMP",LEN(B52)=6) -> TRUE
B53: emp155 | D53: =AND(C52:D52) -> TRUE
B54: emp267
B55: emp100
B56: emp100 | D56: Here duplicates can also be rejected by writing COUNTIF() in AND()
D57: to remove duplicate emp id
...
