Workbook
Name Product_A: Indirect!$B$4:$B$7
Name Product_B: Indirect!$C$4:$C$7
Name Product_C: Indirect!$D$4:$D$7
Name Product_List: 'Product List'!$A$1:$E$299

Sheet Order SUmmary
A1: =IFERROR(_xlfn.FORMULATEXT(F1),"") -> =VLOOKUP(D3, 'Customer Details'!$A$1:$F$17,2,FALSE) | F1: =VLOOKUP(D3, 'Customer Details'!$A$1:$F$17,2,FALSE) -> Sonata Software | H1: =IFERROR(_xlfn.FORMULATEXT(H3),"") -> =VLOOKUP($D3,'Customer Details'!$A$1:$F$17,MATCH('Order SUmmary'!H$2,'Customer Details'!$A$1:$F$1,0),0) | L1: =IFERROR(_xlfn.FORMULATEXT(L3),"") -> =INDEX(Product_List,MATCH($F3,'Product List'!$B$1:$B$299,0),MATCH('Order SUmmary'!L$2,'Product List'!$A$1:$E$1,0)) | P1: =IFERROR(_xlfn.FORMULATEXT(P3),"") -> =HLOOKUP(C3,'Commission Criteria'!$A$2:$I$4,3,FALSE) | S1: =IFERROR(_xlfn.FORMULATEXT(S3),"") -> =VLOOKUP(R3,'Commission Criteria'!$L$3:$M$11,2,TRUE) | T1: =IFERROR(_xlfn.FORMULATEXT(T3),"") -> =IF(P3<5,VLOOKUP(R3,'Commission Criteria'!$L$3:$M$11,2,1),VLOOKUP('Order SUmmary'!R3,'Commission Criteria'!$P$3:$Q$11,2,1)) | U1: =IFERROR(_xlfn.FORMULATEXT(U3),"") -> =VLOOKUP(R3,IF(P3<5,'Commission Criteria'!$L$3:$M$11,'Commission Criteria'!$P$3:$Q$11),2,1) | V1: =IFERROR(_xlfn.FORMULATEXT(X3),"") -> =XLOOKUP(F3,'Product List'!$B$1:$B$299,'Product List'!$A$1:$A$299)
A2: OrderNum | B2: OrderDate | C2: Sales Person | D2: CustomerID | E2: City by Normal Vlookup | F2: ProductID | G2: Quantity | H2: Name | I2: City | J2: Zip | K2: Region | L2: Product | M2: Price | N2: Cost | O2: Product Category | P2: Sales Person Experience | Q2: Total Cost | R2: Total Sales | S2: Sales Person Commission | T2: Sales Person Commission -Criteria | U2: Sales Person Commission -Criteria | V2: Order Source | W2: Discount % | X2: Product Name by Xlookup | Y2: Customer details using Xlookup Array | Z2: Name | AA2: Address | AB2: City | AC2: State | AD2: Zip
A3: NUM000001 | B3: 41282 | C3: ASHWINI | D3: 10011 | E3: =VLOOKUP($D3,'Customer Details'!$A$1:$F$17,4,FALSE) -> Olympia | F3: P0210 | G3: 2 | H3: =VLOOKUP($D3,'Customer Details'!$A$1:$F$17,MATCH('Order SUmmary'!H$2,'Customer Details'!$A$1:$F$1,0),0) -> Sonata Software | I3: =VLOOKUP($D3,'Customer Details'!$A$1:$F$17,4,0) -> Olympia | J3: =VLOOKUP($D3,'Customer Details'!$A$1:$F$17,6,0) -> 98502 | K3: =VLOOKUP(VLOOKUP(D3,'Customer Details'!$A$1:$F$17,5,0),'Region INfo'!$A$1:$C$52,3,0) -> Pacific | L3: =INDEX(Product_List,MATCH($F3,'Product List'!$B$1:$B$299,0),MATCH('Order SUmmary'!L$2,'Product List'!$A$1:$E$1,0)) -> Xerox 1951 | M3: =INDEX(Product_List,MATCH($F3,'Product List'!$B$1:$B$299,0),MATCH('Order SUmmary'!M$2,'Product List'!$A$1:$E$1,0)) -> 4006 | N3: =INDEX(Product_List,MATCH($F3,'Product List'!$B$1:$B$299,0),MATCH('Order SUmmary'!N$2,'Product List'!$A$1:$E$1,0)) -> 1898 | O3: =INDEX(Product_List,MATCH($F3,'Product List'!$B$1:$B$299,0),MATCH('Order SUmmary'!O$2,'Product List'!$A$1:$E$1,0)) -> Paper | P3: =HLOOKUP(C3,'Commission Criteria'!$A$2:$I$4,3,FALSE) -> 4 | Q3: =N3*G3 -> 3796 | R3: =M3*G3 -> 8012 | S3: =VLOOKUP(R3,'Commission Criteria'!$L$3:$M$11,2,TRUE) -> 0.03 | T3: =IF(P3<5,VLOOKUP(R3,'Commission Criteria'!$L$3:$M$11,2,1),VLOOKUP('Order SUmmary'!R3,'Commission Criteria'!$P$3:$Q$11,2,1)) -> 0.03 | U3: =VLOOKUP(R3,IF(P3<5,'Commission Criteria'!$L$3:$M$11,'Commission Criteria'!$P$3:$Q$11),2,1) -> 0.03 | V3: Referral | W3: =VLOOKUP(F3,INDIRECT(V3&"!$A$1:$B$296"),2,0) -> 0.01 | X3: =_xlfn.XLOOKUP(F3,'Product List'!$B$1:$B$299,'Product List'!$A$1:$A$299) -> Xerox 1951 | Z3: {=_xlfn.XLOOKUP(D3,'Customer Details'!$A$1:$A$17,'Customer Details'!$B$1:$F$17,"",0,1)} -> Sonata Software | AA3: 1331 Kimberly Dr. | AB3: Olympia | AC3: WA | AD3: 98502
A4: NUM000002 | B4: 41283 | C4: ASHWINI | D4: 10007 | E4: =VLOOKUP($D4,'Customer Details'!$A$1:$F$17,4,FALSE) -> Richmond | F4: P0134 | G4: 1 | H4: =VLOOKUP($D4,'Customer Details'!$A$1:$F$17,MATCH('Order SUmmary'!H$2,'Customer Details'!$A$1:$F$1,0),0) -> GHCL Ltd. | I4: =VLOOKUP($D4,'Customer Details'!$A$1:$F$17,4,0) -> Richmond | J4: =VLOOKUP($D4,'Customer Details'!$A$1:$F$17,6,0) -> 94805 | K4: =VLOOKUP(VLOOKUP(D4,'Customer Details'!$A$1:$F$17,5,0),'Region INfo'!$A$1:$C$52,3,0) -> Pacific | L4: =INDEX(Product_List,MATCH($F4,'Product List'!$B$1:$B$299,0),MATCH('Order SUmmary'!L$2,'Product List'!$A$1:$E$1,0)) -> Avery 494 | M4: =INDEX(Product_List,MATCH($F4,'Product List'!$B$1:$B$299,0),MATCH('Order SUmmary'!M$2,'Product List'!$A$1:$E$1,0)) -> 2923 | N4: =INDEX(Product_List,MATCH($F4,'Product List'!$B$1:$B$299,0),MATCH('Order SUmmary'!N$2,'Product List'!$A$1:$E$1,0)) -> 2480 | O4: =INDEX(Product_List,MATCH($F4,'Product List'!$B$1:$B$299,0),MATCH('Order SUmmary'!O$2,'Product List'!$A$1:$E$1,0)) -> Labels | P4: =HLOOKUP(C4,'Commission Criteria'!$A$2:$I$4,3,FALSE) -> 4 | Q4: =N4*G4 -> 2480 | R4: =M4*G4 -> 2923 | S4: =VLOOKUP(R4,'Commission Criteria'!$L$3:$M$11,2,TRUE) -> 0.01 | T4: =IF(P4<5,VLOOKUP(R4,'Commission Criteria'!$L$3:$M$11,2,1),VLOOKUP('Order SUmmary'!R4,'Commission Criteria'!$P$3:$Q$11,2,1)) -> 0.01 | U4: =VLOOKUP(R4,IF(P4<5,'Commission Criteria'!$L$3:$M$11,'Commission Criteria'!$P$3:$Q$11),2,1) -> 0.01 | V4: India_mart | W4: =VLOOKUP(F4,INDIRECT(V4&"!$A$1:$B$296"),2,0) -> 0.05 | X4: =_xlfn.XLOOKUP(F4,'Product List'!$B$1:$B$299,'Product List'!$A$1:$A$299) -> Avery 494 | Z4: {=_xlfn.XLOOKUP(D4,'Customer Details'!$A$1:$A$17,'Customer Details'!$B$1:$F$17,"",0,1)} -> GHCL Ltd. | AA4: 58 Clarence St | AB4: Richmond | AC4: CA | AD4: 94805
A5: NUM000002 | B5: 41283 | C5: BHAGYASHRI | D5: 10005 | E5: =VLOOKUP($D5,'Customer Details'!$A$1:$F$17,4,FALSE) -> Goleta | F5: P0141 | G5: 3 | H5: =VLOOKUP($D5,'Customer Details'!$A$1:$F$17,MATCH('Order SUmmary'!H$2,'Customer Details'!$A$1:$F$1,0),0) -> Fortis Healthcare Ltd. | I5: =VLOOKUP($D5,'Customer Details'!$A$1:$F$17,4,0) -> Goleta | J5: =VLOOKUP($D5,'Customer Details'!$A$1:$F$17,6,0) -> 93117 | K5: =VLOOKUP(VLOOKUP(D5,'Customer Details'!$A$1:$F$17,5,0),'Region INfo'!$A$1:$C$52,3,0) -> Pacific | L5: =INDEX(Product_List,MATCH($F5,'Product List'!$B$1:$B$299,0),MATCH('Order SUmmary'!L$2,'Product List'!$A$1:$E$1,0)) -> Xerox 203 | M5: =INDEX(Product_List,MATCH($F5,'Product List'!$B$1:$B$299,0),MATCH('Order SUmmary'!M$2,'Product List'!$A$1:$E$1,0)) -> 3637 | N5: =INDEX(Product_List,MATCH($F5,'Product List'!$B$1:$B$299,0),MATCH('Order SUmmary'!N$2,'Product List'!$A$1:$E$1,0)) -> 2463 | O5: =INDEX(Product_List,MATCH($F5,'Product List'!$B$1:$B$299,0),MATCH('Order SUmmary'!O$2,'Product List'!$A$1:$E$1,0)) -> Paper | P5: =HLOOKUP(C5,'Commission Criteria'!$A$2:$I$4,3,FALSE) -> 1 | Q5: =N5*G5 -> 7389 | R5: =M5*G5 -> 10911 | S5: =VLOOKUP(R5,'Commission Criteria'!$L$3:$M$11,2,TRUE) -> 0.03 | T5: =IF(P5<5,VLOOKUP(R5,'Commission Criteria'!$L$3:$M$11,2,1),VLOOKUP('Order SUmmary'!R5,'Commission Criteria'!$P$3:$Q$11,2,1)) -> 0.03 | U5: =VLOOKUP(R5,IF(P5<5,'Commission Criteria'!$L$3:$M$11,'Commission Criteria'!$P$3:$Q$11),2,1) -> 0.03 | V5: Flipkart | W5: =VLOOKUP(F5,INDIRECT(V5&"!$A$1:$B$296"),2,0) -> 0.04 | X5: =_xlfn.XLOOKUP(F5,'Product List'!$B$1:$B$299,'Product List'!$A$1:$A$299) -> Xerox 203 | Z5: {=_xlfn.XLOOKUP(D5,'Customer Details'!$A$1:$A$17,'Customer Details'!$B$1:$F$17,"",0,1)} -> Fortis Healthcare Ltd. | AA5: 14 Elsworthy Terrace | AB5: Goleta | AC5: CA | AD5: 93117
A6: NUM000002 | B6: 41283 | C6: NEHA | D6: 10008 | E6: =VLOOKUP($D6,'Customer Details'!$A$1:$F$17,4,FALSE) -> Chestnut Ridge | F6: P0081 | G6: 3 | H6: =VLOOKUP($D6,'Customer Details'!$A$1:$F$17,MATCH('Order SUmmary'!H$2,'Customer Details'!$A$1:$F$1,0),0) -> Reliance Industries Limited | I6: =VLOOKUP($D6,'Customer Details'!$A$1:$F$17,4,0) -> Chestnut Ridge | J6: =VLOOKUP($D6,'Customer Details'!$A$1:$F$17,6,0) -> 10977 | K6: =VLOOKUP(VLOOKUP(D6,'Customer Details'!$A$1:$F$17,5,0),'Region INfo'!$A$1:$C$52,3,0) -> Northern | L6: =INDEX(Product_List,MATCH($F6,'Product List'!$B$1:$B$299,0),MATCH('Order SUmmary'!L$2,'Product List'!$A$1:$E$1,0)) -> Avery 508 | M6: =INDEX(Product_List,MATCH($F6,'Product List'!$B$1:$B$299,0),MATCH('Order SUmmary'!M$2,'Product List'!$A$1:$E$1,0)) -> 3788 | N6: =INDEX(Product_List,MATCH($F6,'Product List'!$B$1:$B$299,0),MATCH('Order SUmmary'!N$2,'Product List'!$A$1:$E$1,0)) -> 2170 | O6: =INDEX(Product_List,MATCH($F6,'Product List'!$B$1:$B$299,0),MATCH('Order SUmmary'!O$2,'Product List'!$A$1:$E$1,0)) -> Labels | P6: =HLOOKUP(C6,'Commission Criteria'!$A$2:$I$4,3,FALSE) -> 6 | Q6: =N6*G6 -> 6510 | R6: =M6*G6 -> 11364 | S6: =VLOOKUP(R6,'Commission Criteria'!$L$3:$M$11,2,TRUE) -> 0.03 | T6: =IF(P6<5,VLOOKUP(R6,'Commission Criteria'!$L$3:$M$11,2,1),VLOOKUP('Order SUmmary'!R6,'Commission Criteria'!$P$3:$Q$11,2,1)) -> 0.02 | U6: =VLOOKUP(R6,IF(P6<5,'Commission Criteria'!$L$3:$M$11,'Commission Criteria'!$P$3:$Q$11),2,1) -> 0.02 | V6: Referral | W6: =VLOOKUP(F6,INDIRECT(V6&"!$A$1:$B$296"),2,0) -> 0.03 | X6: =_xlfn.XLOOKUP(F6,'Product List'!$B$1:$B$299,'Product List'!$A$1:$A$299) -> Avery 508 | Z6: {=_xlfn.XLOOKUP(D6,'Customer Details'!$A$1:$A$17,'Customer Details'!$B$1:$F$17,"",0,1)} -> Reliance Industries Limited | AA6: 12020 Shamrock Rd., Suite 333 | AB6: Chestnut Ridge | AC6: NY | AD6: 10977
A7: NUM000003 | B7: 41283 | C7: BHAGYASHRI | D7: 10007 | E7: =VLOOKUP($D7,'Customer Details'!$A$1:$F$17,4,FALSE) -> Richmond | F7: P0256 | G7: 3 | H7: =VLOOKUP($D7,'Customer Details'!$A$1:$F$17,MATCH('Order SUmmary'!H$2,'Customer Details'!$A$1:$F$1,0),0) -> GHCL Ltd. | I7: =VLOOKUP($D7,'Customer Details'!$A$1:$F$17,4,0) -> Richmond | J7: =VLOOKUP($D7,'Customer Details'!$A$1:$F$17,6,0) -> 94805 | K7: =VLOOKUP(VLOOKUP(D7,'Customer Details'!$A$1:$F$17,5,0),'Region INfo'!$A$1:$C$52,3,0) -> Pacific | L7: =INDEX(Product_List,MATCH($F7,'Product List'!$B$1:$B$299,0),MATCH('Order SUmmary'!L$2,'Product List'!$A$1:$E$1,0)) -> Xerox 1890 | M7: =INDEX(Product_List,MATCH($F7,'Product List'!$B$1:$B$299,0),MATCH('Order SUmmary'!M$2,'Product List'!$A$1:$E$1,0)) -> 3878 | N7: =INDEX(Product_List,MATCH($F7,'Product List'!$B$1:$B$299,0),MATCH('Order SUmmary'!N$2,'Product List'!$A$1:$E$1,0)) -> 2236 | O7: =INDEX(Product_List,MATCH($F7,'Product List'!$B$1:$B$299,0),MATCH('Order SUmmary'!O$2,'Product List'!$A$1:$E$1,0)) -> Paper | P7: =HLOOKUP(C7,'Commission Criteria'!$A$2:$I$4,3,FALSE) -> 1 | Q7: =N7*G7 -> 6708 | R7: =M7*G7 -> 11634 | S7: =VLOOKUP(R7,'Commission Criteria'!$L$3:$M$11,2,TRUE) -> 0.03 | T7: =IF(P7<5,VLOOKUP(R7,'Commission Criteria'!$L$3:$M$11,2,1),VLOOKUP('Order SUmmary'!R7,'Commission Criteria'!$P$3:$Q$11,2,1)) -> 0.03 | U7: =VLOOKUP(R7,IF(P7<5,'Commission Criteria'!$L$3:$M$11,'Commission Criteria'!$P$3:$Q$11),2,1) -> 0.03 | V7: Website | W7: =VLOOKUP(F7,INDIRECT(V7&"!$A$1:$B$296"),2,0) -> 0.04 | X7: =_xlfn.XLOOKUP(F7,'Product List'!$B$1:$B$299,'Product List'!$A$1:$A$299) -> Xerox 1890 | Z7: {=_xlfn.XLOOKUP(D7,'Customer Details'!$A$1:$A$17,'Customer Details'!$B$1:$F$17,"",0,1)} -> GHCL Ltd. | AA7: 58 Clarence St | AB7: Richmond | AC7: CA | AD7: 94805
A8: NUM000004 | B8: 41287 | C8: BHAGYASHRI | D8: 10011 | E8: =VLOOKUP($D8,'Customer Details'!$A$1:$F$17,4,FALSE) -> Olympia | F8: P0097 | G8: 1 | H8: =VLOOKUP($D8,'Customer Details'!$A$1:$F$17,MATCH('Order SUmmary'!H$2,'Customer Details'!$A$1:$F$1,0),0) -> Sonata Software | I8: =VLOOKUP($D8,'Customer Details'!$A$1:$F$17,4,0) -> Olympia | J8: =VLOOKUP($D8,'Customer Details'!$A$1:$F$17,6,0) -> 98502 | K8: =VLOOKUP(VLOOKUP(D8,'Customer Details'!$A$1:$F$17,5,0),'Region INfo'!$A$1:$C$52,3,0) -> Pacific | L8: =INDEX(Product_List,MATCH($F8,'Product List'!$B$1:$B$299,0),MATCH('Order SUmmary'!L$2,'Product List'!$A$1:$E$1,0)) -> Staple magnet | M8: =INDEX(Product_List,MATCH($F8,'Product List'!$B$1:$B$299,0),MATCH('Order SUmmary'!M$2,'Product List'!$A$1:$E$1,0)) -> 3993 | N8: =INDEX(Product_List,MATCH($F8,'Product List'!$B$1:$B$299,0),MATCH('Order SUmmary'!N$2,'Product List'!$A$1:$E$1,0)) -> 1338 | O8: =INDEX(Product_List,MATCH($F8,'Product List'!$B$1:$B$299,0),MATCH('Order SUmmary'!O$2,'Product List'!$A$1:$E$1,0)) -> Storage | P8: =HLOOKUP(C8,'Commission Criteria'!$A$2:$I$4,3,FALSE) -> 1 | Q8: =N8*G8 -> 1338 | R8: =M8*G8 -> 3993 | S8: =VLOOKUP(R8,'Commission Criteria'!$L$3:$M$11,2,TRUE) -> 0.01 | T8: =IF(P8<5,VLOOKUP(R8,'Commission Criteria'!$L$3:$M$11,2,1),VLOOKUP('Order SUmmary'!R8,'Commission Criteria'!$P$3:$Q$11,2,1)) -> 0.01 | U8: =VLOOKUP(R8,IF(P8<5,'Commission Criteria'!$L$3:$M$11,'Commission Criteria'!$P$3:$Q$11),2,1) -> 0.01 | V8: Snapdeal | W8: =VLOOKUP(F8,INDIRECT(V8&"!$A$1:$B$296"),2,0) -> 0 | X8: =_xlfn.XLOOKUP(F8,'Product List'!$B$1:$B$299,'Product List'!$A$1:$A$299) -> Staple magnet | Z8: {=_xlfn.XLOOKUP(D8,'Customer Details'!$A$1:$A$17,'Customer Details'!$B$1:$F$17,"",0,1)} -> Sonata Software | AA8: 1331 Kimberly Dr. | AB8: Olympia | AC8: WA | AD8: 98502
A9: NUM000004 | B9: 41287 | C9: NIKITA | D9: 10012 | E9: =VLOOKUP($D9,'Customer Details'!$A$1:$F$17,4,FALSE) -> Santa Barbara | F9: P0094 | G9: 1 | H9: =VLOOKUP($D9,'Customer Details'!$A$1:$F$17,MATCH('Order SUmmary'!H$2,'Customer Details'!$A$1:$F$1,0),0) -> Dynamatic Technologies Ltd. | I9: =VLOOKUP($D9,'Customer Details'!$A$1:$F$17,4,0) -> Santa Barbara | J9: =VLOOKUP($D9,'Customer Details'!$A$1:$F$17,6,0) -> 93110 | K9: =VLOOKUP(VLOOKUP(D9,'Customer Details'!$A$1:$F$17,5,0),'Region INfo'!$A$1:$C$52,3,0) -> Pacific | L9: =INDEX(Product_List,MATCH($F9,'Product List'!$B$1:$B$299,0),MATCH('Order SUmmary'!L$2,'Product List'!$A$1:$E$1,0)) -> Avery 486 | M9: =INDEX(Product_List,MATCH($F9,'Product List'!$B$1:$B$299,0),MATCH('Order SUmmary'!M$2,'Product List'!$A$1:$E$1,0)) -> 4914 | N9: =INDEX(Product_List,MATCH($F9,'Product List'!$B$1:$B$299,0),MATCH('Order SUmmary'!N$2,'Product List'!$A$1:$E$1,0)) -> 1632 | O9: =INDEX(Product_List,MATCH($F9,'Product List'!$B$1:$B$299,0),MATCH('Order SUmmary'!O$2,'Product List'!$A$1:$E$1,0)) -> Labels | P9: =HLOOKUP(C9,'Commission Criteria'!$A$2:$I$4,3,FALSE) -> 4 | Q9: =N9*G9 -> 1632 | R9: =M9*G9 -> 4914 | S9: =VLOOKUP(R9,'Commission Criteria'!$L$3:$M$11,2,TRUE) -> 0.01 | T9: =IF(P9<5,VLOOKUP(R9,'Commission Criteria'!$L$3:$M$11,2,1),VLOOKUP('Order SUmmary'!R9,'Commission Criteria'!$P$3:$Q$11,2,1)) -> 0.01 | U9: =VLOOKUP(R9,IF(P9<5,'Commission Criteria'!$L$3:$M$11,'Commission Criteria'!$P$3:$Q$11),2,1) -> 0.01 | V9: Flipkart | W9: =VLOOKUP(F9,INDIRECT(V9&"!$A$1:$B$296"),2,0) -> 0.04 | X9: =_xlfn.XLOOKUP(F9,'Product List'!$B$1:$B$299,'Product List'!$A$1:$A$299) -> Avery 486 | Z9: {=_xlfn.XLOOKUP(D9,'Customer Details'!$A$1:$A$17,'Customer Details'!$B$1:$F$17,"",0,1)} -> Dynamatic Technologies Ltd. | AA9: 402 Pinkster Lane | AB9: Santa Barbara | AC9: CA | AD9: 93110
A10: NUM000004 | B10: 41287 | C10: APOORVA | D10: 10009 | E10: =VLOOKUP($D10,'Customer Details'!$A$1:$F$17,4,FALSE) -> Salt Lake City | F10: P0240 | G10: 2 | H10: =VLOOKUP($D10,'Customer Details'!$A$1:$F$17,MATCH('Order SUmmary'!H$2,'Customer Details'!$A$1:$F$1,0),0) -> Godfrey Philips India Ltd. | I10: =VLOOKUP($D10,'Customer Details'!$A$1:$F$17,4,0) -> Salt Lake City | J10: =VLOOKUP($D10,'Customer Details'!$A$1:$F$17,6,0) -> 84118 | K10: =VLOOKUP(VLOOKUP(D10,'Customer Details'!$A$1:$F$17,5,0),'Region INfo'!$A$1:$C$52,3,0) -> Pacific | L10: =INDEX(Product_List,MATCH($F10,'Product List'!$B$1:$B$299,0),MATCH('Order SUmmary'!L$2,'Product List'!$A$1:$E$1,0)) -> Xerox 1907 | M10: =INDEX(Product_List,MATCH($F10,'Product List'!$B$1:$B$299,0),MATCH('Order SUmmary'!M$2,'Product List'!$A$1:$E$1,0)) -> 4990 | N10: =INDEX(Product_List,MATCH($F10,'Product List'!$B$1:$B$299,0),MATCH('Order SUmmary'!N$2,'Product List'!$A$1:$E$1,0)) -> 1360 | O10: =INDEX(Product_List,MATCH($F10,'Product List'!$B$1:$B$299,0),MATCH('Order SUmmary'!O$2,'Product List'!$A$1:$E$1,0)) -> Paper | P10: =HLOOKUP(C10,'Commission Criteria'!$A$2:$I$4,3,FALSE) -> 8 | Q10: =N10*G10 -> 2720 | R10: =M10*G10 -> 9980 | S10: =VLOOKUP(R10,'Commission Criteria'!$L$3:$M$11,2,TRUE) -> 0.03 | T10: =IF(P10<5,VLOOKUP(R10,'Commission Criteria'!$L$3:$M$11,2,1),VLOOKUP('Order SUmmary'!R10,'Commission Criteria'!$P$3:$Q$11,2,1)) -> 0.02 | U10: =VLOOKUP(R10,IF(P10<5,'Commission Criteria'!$L$3:$M$11,'Commission Criteria'!$P$3:$Q$11),2,1) -> 0.02 | V10: Flipkart | W10: =VLOOKUP(F10,INDIRECT(V10&"!$A$1:$B$296"),2,0) -> 0.03 | X10: =_xlfn.XLOOKUP(F10,'Product List'!$B$1:$B$299,'Product List'!$A$1:$A$299) -> Xerox 1907 | Z10: {=_xlfn.XLOOKUP(D10,'Customer Details'!$A$1:$A$17,'Customer Details'!$B$1:$F$17,"",0,1)} -> Godfrey Philips India Ltd. | AA10: 20501 Ania Ave #2 | AB10: Salt Lake City | AC10: UT | AD10: 84118
A11: NUM000006 | B11: 41289 | C11: NEHA | D11: 10002 | E11: =VLOOKUP($D11,'Customer Details'!$A$1:$F$17,4,FALSE) -> Omaha | F11: P0133 | G11: 1 | H11: =VLOOKUP($D11,'Customer Details'!$A$1:$F$17,MATCH('Order SUmmary'!H$2,'Customer Details'!$A$1:$F$1,0),0) -> Elder Pharmaceuticals | I11: =VLOOKUP($D11,'Customer Details'!$A$1:$F$17,4,0) -> Omaha | J11: =VLOOKUP($D11,'Customer Details'!$A$1:$F$17,6,0) -> 68127 | K11: =VLOOKUP(VLOOKUP(D11,'Customer Details'!$A$1:$F$17,5,0),'Region INfo'!$A$1:$C$52,3,0) -> Western | L11: =INDEX(Product_List,MATCH($F11,'Product List'!$B$1:$B$299,0),MATCH('Order SUmmary'!L$2,'Product List'!$A$1:$E$1,0)) -> Avery 477 | M11: =INDEX(Product_List,MATCH($F11,'Product List'!$B$1:$B$299,0),MATCH('Order SUmmary'!M$2,'Product List'!$A$1:$E$1,0)) -> 2633 | N11: =INDEX(Product_List,MATCH($F11,'Product List'!$B$1:$B$299,0),MATCH('Order SUmmary'!N$2,'Product List'!$A$1:$E$1,0)) -> 1742 | O11: =INDEX(Product_List,MATCH($F11,'Product List'!$B$1:$B$299,0),MATCH('Order SUmmary'!O$2,'Product List'!$A$1:$E$1,0)) -> Labels | P11: =HLOOKUP(C11,'Commission Criteria'!$A$2:$I$4,3,FALSE) -> 6 | Q11: =N11*G11 -> 1742 | R11: =M11*G11 -> 2633 | S11: =VLOOKUP(R11,'Commission Criteria'!$L$3:$M$11,2,TRUE) -> 0.01 | T11: =IF(P11<5,VLOOKUP(R11,'Commission Criteria'!$L$3:$M$11,2,1),VLOOKUP('Order SUmmary'!R11,'Commission Criteria'!$P$3:$Q$11,2,1)) -> 0.02 | U11: =VLOOKUP(R11,IF(P11<5,'Commission Criteria'!$L$3:$M$11,'Commission Criteria'!$P$3:$Q$11),2,1) -> 0.02 | V11: Amazon | W11: =VLOOKUP(F11,INDIRECT(V11&"!$A$1:$B$296"),2,0) -> 0.04 | X11: =_xlfn.XLOOKUP(F11,'Product List'!$B$1:$B$299,'Product List'!$A$1:$A$299) -> Avery 477 | Z11: {=_xlfn.XLOOKUP(D11,'Customer Details'!$A$1:$A$17,'Customer Details'!$B$1:$F$17,"",0,1)} -> Elder Pharmaceuticals | AA11: 57 Neriba Cres | AB11: Omaha | AC11: NE | AD11: 68127
A12: NUM000006 | B12: 41289 | C12: AJAY | D12: 10010 | E12: =VLOOKUP($D12,'Customer Details'!$A$1:$F$17,4,FALSE) -> Tracy | F12: P0133 | G12: 2 | H12: =VLOOKUP($D12,'Customer Details'!$A$1:$F$17,MATCH('Order SUmmary'!H$2,'Customer Details'!$A$1:$F$1,0),0) -> Suzlon Energy Ltd. | I12: =VLOOKUP($D12,'Customer Details'!$A$1:$F$17,4,0) -> Tracy | J12: =VLOOKUP($D12,'Customer Details'!$A$1:$F$17,6,0) -> 95376 | K12: =VLOOKUP(VLOOKUP(D12,'Customer Details'!$A$1:$F$17,5,0),'Region INfo'!$A$1:$C$52,3,0) -> Pacific | L12: =INDEX(Product_List,MATCH($F12,'Product List'!$B$1:$B$299,0),MATCH('Order SUmmary'!L$2,'Product List'!$A$1:$E$1,0)) -> Avery 477 | M12: =INDEX(Product_List,MATCH($F12,'Product List'!$B$1:$B$299,0),MATCH('Order SUmmary'!M$2,'Product List'!$A$1:$E$1,0)) -> 2633 | N12: =INDEX(Product_List,MATCH($F12,'Product List'!$B$1:$B$299,0),MATCH('Order SUmmary'!N$2,'Product List'!$A$1:$E$1,0)) -> 1742 | O12: =INDEX(Product_List,MATCH($F12,'Product List'!$B$1:$B$299,0),MATCH('Order SUmmary'!O$2,'Product List'!$A$1:$E$1,0)) -> Labels | P12: =HLOOKUP(C12,'Commission Criteria'!$A$2:$I$4,3,FALSE) -> 10 | Q12: =N12*G12 -> 3484 | R12: =M12*G12 -> 5266 | S12: =VLOOKUP(R12,'Commission Criteria'!$L$3:$M$11,2,TRUE) -> 0.03 | T12: =IF(P12<5,VLOOKUP(R12,'Commission Criteria'!$L$3:$M$11,2,1),VLOOKUP('Order SUmmary'!R12,'Commission Criteria'!$P$3:$Q$11,2,1)) -> 0.02 | U12: =VLOOKUP(R12,IF(P12<5,'Commission Criteria'!$L$3:$M$11,'Commission Criteria'!$P$3:$Q$11),2,1) -> 0.02 | V12: Referral | W12: =VLOOKUP(F12,INDIRECT(V12&"!$A$1:$B$296"),2,0) -> 0.01 | X12: =_xlfn.XLOOKUP(F12,'Product List'!$B$1:$B$299,'Product List'!$A$1:$A$299) -> Avery 477 | Z12: {=_xlfn.XLOOKUP(D12,'Customer Details'!$A$1:$A$17,'Customer Details'!$B$1:$F$17,"",0,1)} -> Suzlon Energy Ltd. | AA12: 501 Marsh Trail Circle | AB12: Tracy | AC12: CA | AD12: 95376
A13: NUM000006 | B13: 41289 | C13: AJAY | D13: 10001 | E13: =VLOOKUP($D13,'Customer Details'!$A$1:$F$17,4,FALSE) -> New York | F13: P0053 | G13: 2 | H13: =VLOOKUP($D13,'Customer Details'!$A$1:$F$17,MATCH('Order SUmmary'!H$2,'Customer Details'!$A$1:$F$1,0),0) -> Chambal Fertilisers and Chemicals Ltd. | I13: =VLOOKUP($D13,'Customer Details'!$A$1:$F$17,4,0) -> New York | J13: =VLOOKUP($D13,'Customer Details'!$A$1:$F$17,6,0) -> 10025 | K13: =VLOOKUP(VLOOKUP(D13,'Customer Details'!$A$1:$F$17,5,0),'Region INfo'!$A$1:$C$52,3,0) -> Northern | L13: =INDEX(Product_List,MATCH($F13,'Product List'!$B$1:$B$299,0),MATCH('Order SUmmary'!L$2,'Product List'!$A$1:$E$1,0)) -> Avery 520 | M13: =INDEX(Product_List,MATCH($F13,'Product List'!$B$1:$B$299,0),MATCH('Order SUmmary'!M$2,'Product List'!$A$1:$E$1,0)) -> 2718 | N13: =INDEX(Product_List,MATCH($F13,'Product List'!$B$1:$B$299,0),MATCH('Order SUmmary'!N$2,'Product List'!$A$1:$E$1,0)) -> 2254 | O13: =INDEX(Product_List,MATCH($F13,'Product List'!$B$1:$B$299,0),MATCH('Order SUmmary'!O$2,'Product List'!$A$1:$E$1,0)) -> Labels | P13: =HLOOKUP(C13,'Commission Criteria'!$A$2:$I$4,3,FALSE) -> 10 | Q13: =N13*G13 -> 4508 | R13: =M13*G13 -> 5436 | S13: =VLOOKUP(R13,'Commission Criteria'!$L$3:$M$11,2,TRUE) -> 0.03 | T13: =IF(P13<5,VLOOKUP(R13,'Commission Criteria'!$L$3:$M$11,2,1),VLOOKUP('Order SUmmary'!R13,'Commission Criteria'!$P$3:$Q$11,2,1)) -> 0.02 | U13: =VLOOKUP(R13,IF(P13<5,'Commission Criteria'!$L$3:$M$11,'Commission Criteria'!$P$3:$Q$11),2,1) -> 0.02 | V13: Referral | W13: =VLOOKUP(F13,INDIRECT(V13&"!$A$1:$B$296"),2,0) -> 0.05 | X13: =_xlfn.XLOOKUP(F13,'Product List'!$B$1:$B$299,'Product List'!$A$1:$A$299) -> Avery 520 | Z13: {=_xlfn.XLOOKUP(D13,'Customer Details'!$A$1:$A$17,'Customer Details'!$B$1:$F$17,"",0,1)} -> Chambal Fertilisers and Chemicals Ltd. | AA13: 4951 Indiana Ave. | AB13: New York | AC13: NY | AD13: 10025
A14: NUM000005 | B14: 41289 | C14: FARHIN | D14: 10005 | E14: =VLOOKUP($D14,'Customer Details'!$A$1:$F$17,4,FALSE) -> Goleta | F14: P0290 | G14: 2 | H14: =VLOOKUP($D14,'Customer Details'!$A$1:$F$17,MATCH('Order SUmmary'!H$2,'Customer Details'!$A$1:$F$1,0),0) -> Fortis Healthcare Ltd. | I14: =VLOOKUP($D14,'Customer Details'!$A$1:$F$17,4,0) -> Goleta | J14: =VLOOKUP($D14,'Customer Details'!$A$1:$F$17,6,0) -> 93117 | K14: =VLOOKUP(VLOOKUP(D14,'Customer Details'!$A$1:$F$17,5,0),'Region INfo'!$A$1:$C$52,3,0) -> Pacific | L14: =INDEX(Product_List,MATCH($F14,'Product List'!$B$1:$B$299,0),MATCH('Order SUmmary'!L$2,'Product List'!$A$1:$E$1,0)) -> Xerox 229 | M14: =INDEX(Product_List,MATCH($F14,'Product List'!$B$1:$B$299,0),MATCH('Order SUmmary'!M$2,'Product List'!$A$1:$E$1,0)) -> 2885 | N14: =INDEX(Product_List,MATCH($F14,'Product List'!$B$1:$B$299,0),MATCH('Order SUmmary'!N$2,'Product List'!$A$1:$E$1,0)) -> 1242 | O14: =INDEX(Product_List,MATCH($F14,'Product List'!$B$1:$B$299,0),MATCH('Order SUmmary'!O$2,'Product List'!$A$1:$E$1,0)) -> Paper | P14: =HLOOKUP(C14,'Commission Criteria'!$A$2:$I$4,3,FALSE) -> 3 | Q14: =N14*G14 -> 2484 | R14: =M14*G14 -> 5770 | S14: =VLOOKUP(R14,'Commission Criteria'!$L$3:$M$11,2,TRUE) -> 0.03 | T14: =IF(P14<5,VLOOKUP(R14,'Commission Criteria'!$L$3:$M$11,2,1),VLOOKUP('Order SUmmary'!R14,'Commission Criteria'!$P$3:$Q$11,2,1)) -> 0.03 | U14: =VLOOKUP(R14,IF(P14<5,'Commission Criteria'!$L$3:$M$11,'Commission Criteria'!$P$3:$Q$11),2,1) -> 0.03 | V14: Snapdeal | W14: =VLOOKUP(F14,INDIRECT(V14&"!$A$1:$B$296"),2,0) -> 0.05 | X14: =_xlfn.XLOOKUP(F14,'Product List'!$B$1:$B$299,'Product List'!$A$1:$A$299) -> Xerox 229 | Z14: {=_xlfn.XLOOKUP(D14,'Customer Details'!$A$1:$A$17,'Customer Details'!$B$1:$F$17,"",0,1)} -> Fortis Healthcare Ltd. | AA14: 14 Elsworthy Terrace | AB14: Goleta | AC14: CA | AD14: 93117
... A50: NUM000029 | B50: 41336 | C50: MEEHIR | D50: 10002 | E50: =VLOOKUP($D50,'Customer Details'!$A$1:$F$17,4,FALSE) -> Omaha | F50: P0008 | G50: 9 | H50: =VLOOKUP($D50,'Customer Details'!$A$1:$F$17,MATCH('Order SUmmary'!H$2,'Customer Details'!$A$1:$F$1,0),0) -> Elder Pharmaceuticals | I50: =VLOOKUP($D50,'Customer Details'!$A$1:$F$17,4,0) -> Omaha | J50: =VLOOKUP($D50,'Customer Details'!$A$1:$F$17,6,0) -> 68127 | K50: =VLOOKUP(VLOOKUP(D50,'Customer Details'!$A$1:$F$17,5,0),'Region INfo'!$A$1:$C$52,3,0) -> Western | L50: =INDEX(Product_List,MATCH($F50,'Product List'!$B$1:$B$299,0),MATCH('Order SUmmary'!L$2,'Product List'!$A$1:$E$1,0)) -> Xerox 1943 | M50: =INDEX(Product_List,MATCH($F50,'Product List'!$B$1:$B$299,0),MATCH('Order SUmmary'!M$2,'Product List'!$A$1:$E$1,0)) -> 2529 | N50: =INDEX(Product_List,MATCH($F50,'Product List'!$B$1:$B$299,0),MATCH('Order SUmmary'!N$2,'Product List'!$A$1:$E$1,0)) -> 1630 | O50: =INDEX(Product_List,MATCH($F50,'Product List'!$B$1:$B$299,0),MATCH('Order SUmmary'!O$2,'Product List'!$A$1:$E$1,0)) -> Paper | P50: =HLOOKUP(C50,'Commission Criteria'!$A$2:$I$4,3,FALSE) -> 5 | Q50: =N50*G50 -> 14670 | R50: =M50*G50 -> 22761 | S50: =VLOOKUP(R50,'Commission Criteria'!$L$3:$M$11,2,TRUE) -> 0.03 | T50: =IF(P50<5,VLOOKUP(R50,'Commission Criteria'!$L$3:$M$11,2,1),VLOOKUP('Order SUmmary'!R50,'Commission Criteria'!$P$3:$Q$11,2,1)) -> 0.02 | U50: =VLOOKUP(R50,IF(P50<5,'Commission Criteria'!$L$3:$M$11,'Commission Criteria'!$P$3:$Q$11),2,1) -> 0.02 | V50: Amazon | W50: =VLOOKUP(F50,INDIRECT(V50&"!$A$1:$B$296"),2,0) -> 0.05 | X50: =_xlfn.XLOOKUP(F50,'Product List'!$B$1:$B$299,'Product List'!$A$1:$A$299) -> Xerox 1943 | Z50: {=_xlfn.XLOOKUP(D50,'Customer Details'!$A$1:$A$17,'Customer Details'!$B$1:$F$17,"",0,1)} -> Elder Pharmaceuticals | AA50: 57 Neriba Cres | AB50: Omaha | AC50: NE | AD50: 68127
A51: NUM000032 | B51: 41344 | C51: FARHIN | D51: 10012 | E51: =VLOOKUP($D51,'Customer Details'!$A$1:$F$17,4,FALSE) -> Santa Barbara | F51: P0065 | G51: 1 | H51: =VLOOKUP($D51,'Customer Details'!$A$1:$F$17,MATCH('Order SUmmary'!H$2,'Customer Details'!$A$1:$F$1,0),0) -> Dynamatic Technologies Ltd. | I51: =VLOOKUP($D51,'Customer Details'!$A$1:$F$17,4,0) -> Santa Barbara | J51: =VLOOKUP($D51,'Customer Details'!$A$1:$F$17,6,0) -> 93110 | K51: =VLOOKUP(VLOOKUP(D51,'Customer Details'!$A$1:$F$17,5,0),'Region INfo'!$A$1:$C$52,3,0) -> Pacific | L51: =INDEX(Product_List,MATCH($F51,'Product List'!$B$1:$B$299,0),MATCH('Order SUmmary'!L$2,'Product List'!$A$1:$E$1,0)) -> Newell 332 | M51: =INDEX(Product_List,MATCH($F51,'Product List'!$B$1:$B$299,0),MATCH('Order SUmmary'!M$2,'Product List'!$A$1:$E$1,0)) -> 4623 | N51: =INDEX(Product_List,MATCH($F51,'Product List'!$B$1:$B$299,0),MATCH('Order SUmmary'!N$2,'Product List'!$A$1:$E$1,0)) -> 1878 | O51: =INDEX(Product_List,MATCH($F51,'Product List'!$B$1:$B$299,0),MATCH('Order SUmmary'!O$2,'Product List'!$A$1:$E$1,0)) -> Art | P51: =HLOOKUP(C51,'Commission Criteria'!$A$2:$I$4,3,FALSE) -> 3 | Q51: =N51*G51 -> 1878 | R51: =M51*G51 -> 4623 | S51: =VLOOKUP(R51,'Commission Criteria'!$L$3:$M$11,2,TRUE) -> 0.01 | T51: =IF(P51<5,VLOOKUP(R51,'Commission Criteria'!$L$3:$M$11,2,1),VLOOKUP('Order SUmmary'!R51,'Commission Criteria'!$P$3:$Q$11,2,1)) -> 0.01 | U51: =VLOOKUP(R51,IF(P51<5,'Commission Criteria'!$L$3:$M$11,'Commission Criteria'!$P$3:$Q$11),2,1) -> 0.01 | V51: Amazon | W51: =VLOOKUP(F51,INDIRECT(V51&"!$A$1:$B$296"),2,0) -> 0.04 | X51: =_xlfn.XLOOKUP(F51,'Product List'!$B$1:$B$299,'Product List'!$A$1:$A$299) -> Newell 332 | Z51: {=_xlfn.XLOOKUP(D51,'Customer Details'!$A$1:$A$17,'Customer Details'!$B$1:$F$17,"No such customer",0,1)} -> Dynamatic Technologies Ltd. | AA51: 402 Pinkster Lane | AB51: Santa Barbara | AC51: CA | AD51: 93110
A52: NUM000033 | B52: 41345 | C52: BHAGYASHRI | D52: 10015 | E52: =VLOOKUP($D52,'Customer Details'!$A$1:$F$17,4,FALSE) -> South Windsor | F52: P0059 | G52: 1 | H52: =VLOOKUP($D52,'Customer Details'!$A$1:$F$17,MATCH('Order SUmmary'!H$2,'Customer Details'!$A$1:$F$1,0),0) -> Punj Lloyd Ltd. | I52: =VLOOKUP($D52,'Customer Details'!$A$1:$F$17,4,0) -> South Windsor | J52: =VLOOKUP($D52,'Customer Details'!$A$1:$F$17,6,0) -> 06074 | K52: =VLOOKUP(VLOOKUP(D52,'Customer Details'!$A$1:$F$17,5,0),'Region INfo'!$A$1:$C$52,3,0) -> Northern | L52: =INDEX(Product_List,MATCH($F52,'Product List'!$B$1:$B$299,0),MATCH('Order SUmmary'!L$2,'Product List'!$A$1:$E$1,0)) -> Newell 317 | M52: =INDEX(Product_List,MATCH($F52,'Product List'!$B$1:$B$299,0),MATCH('Order SUmmary'!M$2,'Product List'!$A$1:$E$1,0)) -> 4891 | N52: =INDEX(Product_List,MATCH($F52,'Product List'!$B$1:$B$299,0),MATCH('Order SUmmary'!N$2,'Product List'!$A$1:$E$1,0)) -> 1745 | O52: =INDEX(Product_List,MATCH($F52,'Product List'!$B$1:$B$299,0),MATCH('Order SUmmary'!O$2,'Product List'!$A$1:$E$1,0)) -> Art | P52: =HLOOKUP(C52,'Commission Criteria'!$A$2:$I$4,3,FALSE) -> 1 | Q52: =N52*G52 -> 1745 | R52: =M52*G52 -> 4891 | S52: =VLOOKUP(R52,'Commission Criteria'!$L$3:$M$11,2,TRUE) -> 0.01 | T52: =IF(P52<5,VLOOKUP(R52,'Commission Criteria'!$L$3:$M$11,2,1),VLOOKUP('Order SUmmary'!R52,'Commission Criteria'!$P$3:$Q$11,2,1)) -> 0.01 | U52: =VLOOKUP(R52,IF(P52<5,'Commission Criteria'!$L$3:$M$11,'Commission Criteria'!$P$3:$Q$11),2,1) -> 0.01 | V52: Snapdeal | W52: =VLOOKUP(F52,INDIRECT(V52&"!$A$1:$B$296"),2,0) -> 0.05 | X52: =_xlfn.XLOOKUP(F52,'Product List'!$B$1:$B$299,'Product List'!$A$1:$A$299) -> Newell 317 | Z52: {=_xlfn.XLOOKUP(D52,'Customer Details'!$A$1:$A$17,'Customer Details'!$B$1:$F$17,"No such customer",0,1)} -> Punj Lloyd Ltd. | AA52: Box 3263 | AB52: South Windsor | AC52: CT | AD52: 06074
A53: NUM000034 | B53: 41352 | C53: MEEHIR | D53: 10003 | E53: =VLOOKUP($D53,'Customer Details'!$A$1:$F$17,4,FALSE) -> Miami | F53: P0101 | G53: 1 | H53: =VLOOKUP($D53,'Customer Details'!$A$1:$F$17,MATCH('Order SUmmary'!H$2,'Customer Details'!$A$1:$F$1,0),0) -> Honeywell Automation | I53: =VLOOKUP($D53,'Customer Details'!$A$1:$F$17,4,0) -> Miami | J53: =VLOOKUP($D53,'Customer Details'!$A$1:$F$17,6,0) -> 33732 | K53: =VLOOKUP(VLOOKUP(D53,'Customer Details'!$A$1:$F$17,5,0),'Region INfo'!$A$1:$C$52,3,0) -> Southern | L53: =INDEX(Product_List,MATCH($F53,'Product List'!$B$1:$B$299,0),MATCH('Order SUmmary'!L$2,'Product List'!$A$1:$E$1,0)) -> Xerox 1910 | M53: =INDEX(Product_List,MATCH($F53,'Product List'!$B$1:$B$299,0),MATCH('Order SUmmary'!M$2,'Product List'!$A$1:$E$1,0)) -> 2588 | N53: =INDEX(Product_List,MATCH($F53,'Product List'!$B$1:$B$299,0),MATCH('Order SUmmary'!N$2,'Product List'!$A$1:$E$1,0)) -> 2069 | O53: =INDEX(Product_List,MATCH($F53,'Product List'!$B$1:$B$299,0),MATCH('Order SUmmary'!O$2,'Product List'!$A$1:$E$1,0)) -> Paper | P53: =HLOOKUP(C53,'Commission Criteria'!$A$2:$I$4,3,FALSE) -> 5 | Q53: =N53*G53 -> 2069 | R53: =M53*G53 -> 2588 | S53: =VLOOKUP(R53,'Commission Criteria'!$L$3:$M$11,2,TRUE) -> 0.01 | T53: =IF(P53<5,VLOOKUP(R53,'Commission Criteria'!$L$3:$M$11,2,1),VLOOKUP('Order SUmmary'!R53,'Commission Criteria'!$P$3:$Q$11,2,1)) -> 0.02 | U53: =VLOOKUP(R53,IF(P53<5,'Commission Criteria'!$L$3:$M$11,'Commission Criteria'!$P$3:$Q$11),2,1) -> 0.02 | V53: Flipkart | W53: =VLOOKUP(F53,INDIRECT(V53&"!$A$1:$B$296"),2,0) -> 0.03 | X53: =_xlfn.XLOOKUP(F53,'Product List'!$B$1:$B$299,'Product List'!$A$1:$A$299) -> Xerox 1910 | Z53: {=_xlfn.XLOOKUP(D53,'Customer Details'!$A$1:$A$17,'Customer Details'!$B$1:$F$17,"No such customer",0,1)} -> Honeywell Automation | AA53: 1272 Harbor Road | AB53: Miami | AC53: FL | AD53: 33732
A54: NUM000036 | B54: 41356 | C54: BHAGYASHRI | D54: 10011 | E54: =VLOOKUP($D54,'Customer Details'!$A$1:$F$17,4,FALSE) -> Olympia | F54: P0119 | G54: 1 | H54: =VLOOKUP($D54,'Customer Details'!$A$1:$F$17,MATCH('Order SUmmary'!H$2,'Customer Details'!$A$1:$F$1,0),0) -> Sonata Software | I54: =VLOOKUP($D54,'Customer Details'!$A$1:$F$17,4,0) -> Olympia | J54: =VLOOKUP($D54,'Customer Details'!$A$1:$F$17,6,0) -> 98502 | K54: =VLOOKUP(VLOOKUP(D54,'Customer Details'!$A$1:$F$17,5,0),'Region INfo'!$A$1:$C$52,3,0) -> Pacific | L54: =INDEX(Product_List,MATCH($F54,'Product List'!$B$1:$B$299,0),MATCH('Order SUmmary'!L$2,'Product List'!$A$1:$E$1,0)) -> Newell 326 | M54: =INDEX(Product_List,MATCH($F54,'Product List'!$B$1:$B$299,0),MATCH('Order SUmmary'!M$2,'Product List'!$A$1:$E$1,0)) -> 3645 | N54: =INDEX(Product_List,MATCH($F54,'Product List'!$B$1:$B$299,0),MATCH('Order SUmmary'!N$2,'Product List'!$A$1:$E$1,0)) -> 2466 | O54: =INDEX(Product_List,MATCH($F54,'Product List'!$B$1:$B$299,0),MATCH('Order SUmmary'!O$2,'Product List'!$A$1:$E$1,0)) -> Art | P54: =HLOOKUP(C54,'Commission Criteria'!$A$2:$I$4,3,FALSE) -> 1 | Q54: =N54*G54 -> 2466 | R54: =M54*G54 -> 3645 | S54: =VLOOKUP(R54,'Commission Criteria'!$L$3:$M$11,2,TRUE) -> 0.01 | T54: =IF(P54<5,VLOOKUP(R54,'Commission Criteria'!$L$3:$M$11,2,1),VLOOKUP('Order SUmmary'!R54,'Commission Criteria'!$P$3:$Q$11,2,1)) -> 0.01 | U54: =VLOOKUP(R54,IF(P54<5,'Commission Criteria'!$L$3:$M$11,'Commission Criteria'!$P$3:$Q$11),2,1) -> 0.01 | V54: Amazon | W54: =VLOOKUP(F54,INDIRECT(V54&"!$A$1:$B$296"),2,0) -> 0.04 | X54: =_xlfn.XLOOKUP(F54,'Product List'!$B$1:$B$299,'Product List'!$A$1:$A$299) -> Newell 326 | Z54: {=_xlfn.XLOOKUP(D54,'Customer Details'!$A$1:$A$17,'Customer Details'!$B$1:$F$17,"No such customer",0,1)} -> Sonata Software | AA54: 1331 Kimberly Dr. | AB54: Olympia | AC54: WA | AD54: 98502
A55: NUM000037 | B55: 41357 | C55: NIKITA | D55: 10005 | E55: =VLOOKUP($D55,'Customer Details'!$A$1:$F$17,4,FALSE) -> Goleta | F55: P0178 | G55: 2 | H55: =VLOOKUP($D55,'Customer Details'!$A$1:$F$17,MATCH('Order SUmmary'!H$2,'Customer Details'!$A$1:$F$1,0),0) -> Fortis Healthcare Ltd. | I55: =VLOOKUP($D55,'Customer Details'!$A$1:$F$17,4,0) -> Goleta | J55: =VLOOKUP($D55,'Customer Details'!$A$1:$F$17,6,0) -> 93117 | K55: =VLOOKUP(VLOOKUP(D55,'Customer Details'!$A$1:$F$17,5,0),'Region INfo'!$A$1:$C$52,3,0) -> Pacific | L55: =INDEX(Product_List,MATCH($F55,'Product List'!$B$1:$B$299,0),MATCH('Order SUmmary'!L$2,'Product List'!$A$1:$E$1,0)) -> Xerox 1998 | M55: =INDEX(Product_List,MATCH($F55,'Product List'!$B$1:$B$299,0),MATCH('Order SUmmary'!M$2,'Product List'!$A$1:$E$1,0)) -> 4003 | N55: =INDEX(Product_List,MATCH($F55,'Product List'!$B$1:$B$299,0),MATCH('Order SUmmary'!N$2,'Product List'!$A$1:$E$1,0)) -> 2255 | O55: =INDEX(Product_List,MATCH($F55,'Product List'!$B$1:$B$299,0),MATCH('Order SUmmary'!O$2,'Product List'!$A$1:$E$1,0)) -> Paper | P55: =HLOOKUP(C55,'Commission Criteria'!$A$2:$I$4,3,FALSE) -> 4 | Q55: =N55*G55 -> 4510 | R55: =M55*G55 -> 8006 | S55: =VLOOKUP(R55,'Commission Criteria'!$L$3:$M$11,2,TRUE) -> 0.03 | T55: =IF(P55<5,VLOOKUP(R55,'Commission Criteria'!$L$3:$M$11,2,1),VLOOKUP('Order SUmmary'!R55,'Commission Criteria'!$P$3:$Q$11,2,1)) -> 0.03 | U55: =VLOOKUP(R55,IF(P55<5,'Commission Criteria'!$L$3:$M$11,'Commission Criteria'!$P$3:$Q$11),2,1) -> 0.03 | V55: Snapdeal | W55: =VLOOKUP(F55,INDIRECT(V55&"!$A$1:$B$296"),2,0) -> 0.05 | X55: =_xlfn.XLOOKUP(F55,'Product List'!$B$1:$B$299,'Product List'!$A$1:$A$299) -> Xerox 1998 | Z55: {=_xlfn.XLOOKUP(D55,'Customer Details'!$A$1:$A$17,'Customer Details'!$B$1:$F$17,"No such customer",0,1)} -> Fortis Healthcare Ltd. | AA55: 14 Elsworthy Terrace | AB55: Goleta | AC55: CA | AD55: 93117
A56: NUM000040 | B56: 41361 | C56: AJAY | D56: 10009 | E56: =VLOOKUP($D56,'Customer Details'!$A$1:$F$17,4,FALSE) -> Salt Lake City | F56: P0283 | G56: 1 | H56: =VLOOKUP($D56,'Customer Details'!$A$1:$F$17,MATCH('Order SUmmary'!H$2,'Customer Details'!$A$1:$F$1,0),0) -> Godfrey Philips India Ltd. | I56: =VLOOKUP($D56,'Customer Details'!$A$1:$F$17,4,0) -> Salt Lake City | J56: =VLOOKUP($D56,'Customer Details'!$A$1:$F$17,6,0) -> 84118 | K56: =VLOOKUP(VLOOKUP(D56,'Customer Details'!$A$1:$F$17,5,0),'Region INfo'!$A$1:$C$52,3,0) -> Pacific | L56: =INDEX(Product_List,MATCH($F56,'Product List'!$B$1:$B$299,0),MATCH('Order SUmmary'!L$2,'Product List'!$A$1:$E$1,0)) -> Xerox 1902 | M56: =INDEX(Product_List,MATCH($F56,'Product List'!$B$1:$B$299,0),MATCH('Order SUmmary'!M$2,'Product List'!$A$1:$E$1,0)) -> 4172 | N56: =INDEX(Product_List,MATCH($F56,'Product List'!$B$1:$B$299,0),MATCH('Order SUmmary'!N$2,'Product List'!$A$1:$E$1,0)) -> 1415 | O56: =INDEX(Product_List,MATCH($F56,'Product List'!$B$1:$B$299,0),MATCH('Order SUmmary'!O$2,'Product List'!$A$1:$E$1,0)) -> Paper | P56: =HLOOKUP(C56,'Commission Criteria'!$A$2:$I$4,3,FALSE) -> 10 | Q56: =N56*G56 -> 1415 | R56: =M56*G56 -> 4172 | S56: =VLOOKUP(R56,'Commission Criteria'!$L$3:$M$11,2,TRUE) -> 0.01 | T56: =IF(P56<5,VLOOKUP(R56,'Commission Criteria'!$L$3:$M$11,2,1),VLOOKUP('Order SUmmary'!R56,'Commission Criteria'!$P$3:$Q$11,2,1)) -> 0.02 | U56: =VLOOKUP(R56,IF(P56<5,'Commission Criteria'!$L$3:$M$11,'Commission Criteria'!$P$3:$Q$11),2,1) -> 0.02 | V56: India_mart | W56: =VLOOKUP(F56,INDIRECT(V56&"!$A$1:$B$296"),2,0) -> 0.05 | X56: =_xlfn.XLOOKUP(F56,'Product List'!$B$1:$B$299,'Product List'!$A$1:$A$299) -> Xerox 1902 | Z56: {=_xlfn.XLOOKUP(D56,'Customer Details'!$A$1:$A$17,'Customer Details'!$B$1:$F$17,"No such customer",0,1)} -> Godfrey Philips India Ltd. | AA56: 20501 Ania Ave #2 | AB56: Salt Lake City | AC56: UT | AD56: 84118
A57: NUM000038 | B57: 41361 | C57: FARHIN | D57: 10004 | E57: =VLOOKUP($D57,'Customer Details'!$A$1:$F$17,4,FALSE) -> New York | F57: P0182 | G57: 1 | H57: =VLOOKUP($D57,'Customer Details'!$A$1:$F$17,MATCH('Order SUmmary'!H$2,'Customer Details'!$A$1:$F$1,0),0) -> Lupin Ltd. | I57: =VLOOKUP($D57,'Customer Details'!$A$1:$F$17,4,0) -> New York | J57: =VLOOKUP($D57,'Customer Details'!$A$1:$F$17,6,0) -> 10019 | K57: =VLOOKUP(VLOOKUP(D57,'Customer Details'!$A$1:$F$17,5,0),'Region INfo'!$A$1:$C$52,3,0) -> Northern | L57: =INDEX(Product_List,MATCH($F57,'Product List'!$B$1:$B$299,0),MATCH('Order SUmmary'!L$2,'Product List'!$A$1:$E$1,0)) -> Avery 510 | M57: =INDEX(Product_List,MATCH($F57,'Product List'!$B$1:$B$299,0),MATCH('Order SUmmary'!M$2,'Product List'!$A$1:$E$1,0)) -> 4788 | N57: =INDEX(Product_List,MATCH($F57,'Product List'!$B$1:$B$299,0),MATCH('Order SUmmary'!N$2,'Product List'!$A$1:$E$1,0)) -> 2063 | O57: =INDEX(Product_List,MATCH($F57,'Product List'!$B$1:$B$299,0),MATCH('Order SUmmary'!O$2,'Product List'!$A$1:$E$1,0)) -> Labels | P57: =HLOOKUP(C57,'Commission Criteria'!$A$2:$I$4,3,FALSE) -> 3 | Q57: =N57*G57 -> 2063 | R57: =M57*G57 -> 4788 | S57: =VLOOKUP(R57,'Commission Criteria'!$L$3:$M$11,2,TRUE) -> 0.01 | T57: =IF(P57<5,VLOOKUP(R57,'Commission Criteria'!$L$3:$M$11,2,1),VLOOKUP('Order SUmmary'!R57,'Commission Criteria'!$P$3:$Q$11,2,1)) -> 0.01 | U57: =VLOOKUP(R57,IF(P57<5,'Commission Criteria'!$L$3:$M$11,'Commission Criteria'!$P$3:$Q$11),2,1) -> 0.01 | V57: Referral | W57: =VLOOKUP(F57,INDIRECT(V57&"!$A$1:$B$296"),2,0) -> 0.03 | X57: =_xlfn.XLOOKUP(F57,'Product List'!$B$1:$B$299,'Product List'!$A$1:$A$299) -> Avery 510 | Z57: {=_xlfn.XLOOKUP(D57,'Customer Details'!$A$1:$A$17,'Customer Details'!$B$1:$F$17,"No such customer",0,1)} -> Lupin Ltd. | AA57: Abbey Wood | AB57: New York | AC57: NY | AD57: 10019
A58: NUM000040 | B58: 41361 | C58: NIKITA | D58: 10007 | E58: =VLOOKUP($D58,'Customer Details'!$A$1:$F$17,4,FALSE) -> Richmond | F58: P0264 | G58: 2 | H58: =VLOOKUP($D58,'Customer Details'!$A$1:$F$17,MATCH('Order SUmmary'!H$2,'Customer Details'!$A$1:$F$1,0),0) -> GHCL Ltd. | I58: =VLOOKUP($D58,'Customer Details'!$A$1:$F$17,4,0) -> Richmond | J58: =VLOOKUP($D58,'Customer Details'!$A$1:$F$17,6,0) -> 94805 | K58: =VLOOKUP(VLOOKUP(D58,'Customer Details'!$A$1:$F$17,5,0),'Region INfo'!$A$1:$C$52,3,0) -> Pacific | L58: =INDEX(Product_List,MATCH($F58,'Product List'!$B$1:$B$299,0),MATCH('Order SUmmary'!L$2,'Product List'!$A$1:$E$1,0)) -> Avery 503 | M58: =INDEX(Product_List,MATCH($F58,'Product List'!$B$1:$B$299,0),MATCH('Order SUmmary'!M$2,'Product List'!$A$1:$E$1,0)) -> 2820 | N58: =INDEX(Product_List,MATCH($F58,'Product List'!$B$1:$B$299,0),MATCH('Order SUmmary'!N$2,'Product List'!$A$1:$E$1,0)) -> 1504 | O58: =INDEX(Product_List,MATCH($F58,'Product List'!$B$1:$B$299,0),MATCH('Order SUmmary'!O$2,'Product List'!$A$1:$E$1,0)) -> Labels | P58: =HLOOKUP(C58,'Commission Criteria'!$A$2:$I$4,3,FALSE) -> 4 | Q58: =N58*G58 -> 3008 | R58: =M58*G58 -> 5640 | S58: =VLOOKUP(R58,'Commission Criteria'!$L$3:$M$11,2,TRUE) -> 0.03 | T58: =IF(P58<5,VLOOKUP(R58,'Commission Criteria'!$L$3:$M$11,2,1),VLOOKUP('Order SUmmary'!R58,'Commission Criteria'!$P$3:$Q$11,2,1)) -> 0.03 | U58: =VLOOKUP(R58,IF(P58<5,'Commission Criteria'!$L$3:$M$11,'Commission Criteria'!$P$3:$Q$11),2,1) -> 0.03 | V58: India_mart | W58: =VLOOKUP(F58,INDIRECT(V58&"!$A$1:$B$296"),2,0) -> 0.04 | X58: =_xlfn.XLOOKUP(F58,'Product List'!$B$1:$B$299,'Product List'!$A$1:$A$299) -> Avery 503 | Z58: {=_xlfn.XLOOKUP(D58,'Customer Details'!$A$1:$A$17,'Customer Details'!$B$1:$F$17,"No such customer",0,1)} -> GHCL Ltd. | AA58: 58 Clarence St | AB58: Richmond | AC58: CA | AD58: 94805
A59: NUM000039 | B59: 41361 | C59: AJAY | D59: 10003 | E59: =VLOOKUP($D59,'Customer Details'!$A$1:$F$17,4,FALSE) -> Miami | F59: P0012 | G59: 2 | H59: =VLOOKUP($D59,'Customer Details'!$A$1:$F$17,MATCH('Order SUmmary'!H$2,'Customer Details'!$A$1:$F$1,0),0) -> Honeywell Automation | I59: =VLOOKUP($D59,'Customer Details'!$A$1:$F$17,4,0) -> Miami | J59: =VLOOKUP($D59,'Customer Details'!$A$1:$F$17,6,0) -> 33732 | K59: =VLOOKUP(VLOOKUP(D59,'Customer Details'!$A$1:$F$17,5,0),'Region INfo'!$A$1:$C$52,3,0) -> Southern | L59: =INDEX(Product_List,MATCH($F59,'Product List'!$B$1:$B$299,0),MATCH('Order SUmmary'!L$2,'Product List'!$A$1:$E$1,0)) -> Xerox 1921 | M59: =INDEX(Product_List,MATCH($F59,'Product List'!$B$1:$B$299,0),MATCH('Order SUmmary'!M$2,'Product List'!$A$1:$E$1,0)) -> 3150 | N59: =INDEX(Product_List,MATCH($F59,'Product List'!$B$1:$B$299,0),MATCH('Order SUmmary'!N$2,'Product List'!$A$1:$E$1,0)) -> 1218 | O59: =INDEX(Product_List,MATCH($F59,'Product List'!$B$1:$B$299,0),MATCH('Order SUmmary'!O$2,'Product List'!$A$1:$E$1,0)) -> Paper | P59: =HLOOKUP(C59,'Commission Criteria'!$A$2:$I$4,3,FALSE) -> 10 | Q59: =N59*G59 -> 2436 | R59: =M59*G59 -> 6300 | S59: =VLOOKUP(R59,'Commission Criteria'!$L$3:$M$11,2,TRUE) -> 0.03 | T59: =IF(P59<5,VLOOKUP(R59,'Commission Criteria'!$L$3:$M$11,2,1),VLOOKUP('Order SUmmary'!R59,'Commission Criteria'!$P$3:$Q$11,2,1)) -> 0.02 | U59: =VLOOKUP(R59,IF(P59<5,'Commission Criteria'!$L$3:$M$11,'Commission Criteria'!$P$3:$Q$11),2,1) -> 0.02 | V59: Snapdeal | W59: =VLOOKUP(F59,INDIRECT(V59&"!$A$1:$B$296"),2,0) -> 0.02 | X59: =_xlfn.XLOOKUP(F59,'Product List'!$B$1:$B$299,'Product List'!$A$1:$A$299) -> Xerox 1921 | Z59: {=_xlfn.XLOOKUP(D59,'Customer Details'!$A$1:$A$17,'Customer Details'!$B$1:$F$17,"No such customer",0,1)} -> Honeywell Automation | AA59: 1272 Harbor Road | AB59: Miami | AC59: FL | AD59: 33732
A60: NUM000040 | B60: 41361 | C60: FARHIN | D60: 10004 | E60: =VLOOKUP($D60,'Customer Details'!$A$1:$F$17,4,FALSE) -> New York | F60: P0080 | G60: 2 | H60: =VLOOKUP($D60,'Customer Details'!$A$1:$F$17,MATCH('Order SUmmary'!H$2,'Customer Details'!$A$1:$F$1,0),0) -> Lupin Ltd. | I60: =VLOOKUP($D60,'Customer Details'!$A$1:$F$17,4,0) -> New York | J60: =VLOOKUP($D60,'Customer Details'!$A$1:$F$17,6,0) -> 10019 | K60: =VLOOKUP(VLOOKUP(D60,'Customer Details'!$A$1:$F$17,5,0),'Region INfo'!$A$1:$C$52,3,0) -> Northern | L60: =INDEX(Product_List,MATCH($F60,'Product List'!$B$1:$B$299,0),MATCH('Order SUmmary'!L$2,'Product List'!$A$1:$E$1,0)) -> Xerox 1964 | M60: =INDEX(Product_List,MATCH($F60,'Product List'!$B$1:$B$299,0),MATCH('Order SUmmary'!M$2,'Product List'!$A$1:$E$1,0)) -> 4477 | N60: =INDEX(Product_List,MATCH($F60,'Product List'!$B$1:$B$299,0),MATCH('Order SUmmary'!N$2,'Product List'!$A$1:$E$1,0)) -> 1589 | O60: =INDEX(Product_List,MATCH($F60,'Product List'!$B$1:$B$299,0),MATCH('Order SUmmary'!O$2,'Product List'!$A$1:$E$1,0)) -> Paper | P60: =HLOOKUP(C60,'Commission Criteria'!$A$2:$I$4,3,FALSE) -> 3 | Q60: =N60*G60 -> 3178 | R60: =M60*G60 -> 8954 | S60: =VLOOKUP(R60,'Commission Criteria'!$L$3:$M$11,2,TRUE) -> 0.03 | T60: =IF(P60<5,VLOOKUP(R60,'Commission Criteria'!$L$3:$M$11,2,1),VLOOKUP('Order SUmmary'!R60,'Commission Criteria'!$P$3:$Q$11,2,1)) -> 0.03 | U60: =VLOOKUP(R60,IF(P60<5,'Commission Criteria'!$L$3:$M$11,'Commission Criteria'!$P$3:$Q$11),2,1) -> 0.03 | V60: Website | W60: =VLOOKUP(F60,INDIRECT(V60&"!$A$1:$B$296"),2,0) -> 0.03 | X60: =_xlfn.XLOOKUP(F60,'Product List'!$B$1:$B$299,'Product List'!$A$1:$A$299) -> Xerox 1964 | Z60: {=_xlfn.XLOOKUP(D60,'Customer Details'!$A$1:$A$17,'Customer Details'!$B$1:$F$17,"No such customer",0,1)} -> Lupin Ltd. | AA60: Abbey Wood | AB60: New York | AC60: NY | AD60: 10019
A61: NUM000041 | B61: 41361 | C61: NEHA | D61: 10002 | E61: =VLOOKUP($D61,'Customer Details'!$A$1:$F$17,4,FALSE) -> Omaha | F61: P0273 | G61: 3 | H61: =VLOOKUP($D61,'Customer Details'!$A$1:$F$17,MATCH('Order SUmmary'!H$2,'Customer Details'!$A$1:$F$1,0),0) -> Elder Pharmaceuticals | I61: =VLOOKUP($D61,'Customer Details'!$A$1:$F$17,4,0) -> Omaha | J61: =VLOOKUP($D61,'Customer Details'!$A$1:$F$17,6,0) -> 68127 | K61: =VLOOKUP(VLOOKUP(D61,'Customer Details'!$A$1:$F$17,5,0),'Region INfo'!$A$1:$C$52,3,0) -> Western | L61: =INDEX(Product_List,MATCH($F61,'Product List'!$B$1:$B$299,0),MATCH('Order SUmmary'!L$2,'Product List'!$A$1:$E$1,0)) -> Xerox 19 | M61: =INDEX(Product_List,MATCH($F61,'Product List'!$B$1:$B$299,0),MATCH('Order SUmmary'!M$2,'Product List'!$A$1:$E$1,0)) -> 4845 | N61: =INDEX(Product_List,MATCH($F61,'Product List'!$B$1:$B$299,0),MATCH('Order SUmmary'!N$2,'Product List'!$A$1:$E$1,0)) -> 1433 | O61: =INDEX(Product_List,MATCH($F61,'Product List'!$B$1:$B$299,0),MATCH('Order SUmmary'!O$2,'Product List'!$A$1:$E$1,0)) -> Paper | P61: =HLOOKUP(C61,'Commission Criteria'!$A$2:$I$4,3,FALSE) -> 6 | Q61: =N61*G61 -> 4299 | R61: =M61*G61 -> 14535 | S61: =VLOOKUP(R61,'Commission Criteria'!$L$3:$M$11,2,TRUE) -> 0.03 | T61: =IF(P61<5,VLOOKUP(R61,'Commission Criteria'!$L$3:$M$11,2,1),VLOOKUP('Order SUmmary'!R61,'Commission Criteria'!$P$3:$Q$11,2,1)) -> 0.02 | U61: =VLOOKUP(R61,IF(P61<5,'Commission Criteria'!$L$3:$M$11,'Commission Criteria'!$P$3:$Q$11),2,1) -> 0.02 | V61: Referral | W61: =VLOOKUP(F61,INDIRECT(V61&"!$A$1:$B$296"),2,0) -> 0.01 | X61: =_xlfn.XLOOKUP(F61,'Product List'!$B$1:$B$299,'Product List'!$A$1:$A$299) -> Xerox 19 | Z61: {=_xlfn.XLOOKUP(D61,'Customer Details'!$A$1:$A$17,'Customer Details'!$B$1:$F$17,"No such customer",0,1)} -> Elder Pharmaceuticals | AA61: 57 Neriba Cres | AB61: Omaha | AC61: NE | AD61: 68127
A62: NUM000042 | B62: 41363 | C62: APOORVA | D62: 10007 | E62: =VLOOKUP($D62,'Customer Details'!$A$1:$F$17,4,FALSE) -> Richmond | F62: P0107 | G62: 1 | H62: =VLOOKUP($D62,'Customer Details'!$A$1:$F$17,MATCH('Order SUmmary'!H$2,'Customer Details'!$A$1:$F$1,0),0) -> GHCL Ltd. | I62: =VLOOKUP($D62,'Customer Details'!$A$1:$F$17,4,0) -> Richmond | J62: =VLOOKUP($D62,'Customer Details'!$A$1:$F$17,6,0) -> 94805 | K62: =VLOOKUP(VLOOKUP(D62,'Customer Details'!$A$1:$F$17,5,0),'Region INfo'!$A$1:$C$52,3,0) -> Pacific | L62: =INDEX(Product_List,MATCH($F62,'Product List'!$B$1:$B$299,0),MATCH('Order SUmmary'!L$2,'Product List'!$A$1:$E$1,0)) -> Xerox 212 | M62: =INDEX(Product_List,MATCH($F62,'Product List'!$B$1:$B$299,0),MATCH('Order SUmmary'!M$2,'Product List'!$A$1:$E$1,0)) -> 4564 | N62: =INDEX(Product_List,MATCH($F62,'Product List'!$B$1:$B$299,0),MATCH('Order SUmmary'!N$2,'Product List'!$A$1:$E$1,0)) -> 1823 | O62: =INDEX(Product_List,MATCH($F62,'Product List'!$B$1:$B$299,0),MATCH('Order SUmmary'!O$2,'Product List'!$A$1:$E$1,0)) -> Paper | P62: =HLOOKUP(C62,'Commission Criteria'!$A$2:$I$4,3,FALSE) -> 8 | Q62: =N62*G62 -> 1823 | R62: =M62*G62 -> 4564 | S62: =VLOOKUP(R62,'Commission Criteria'!$L$3:$M$11,2,TRUE) -> 0.01 | T62: =IF(P62<5,VLOOKUP(R62,'Commission Criteria'!$L$3:$M$11,2,1),VLOOKUP('Order SUmmary'!R62,'Commission Criteria'!$P$3:$Q$11,2,1)) -> 0.02 | U62: =VLOOKUP(R62,IF(P62<5,'Commission Criteria'!$L$3:$M$11,'Commission Criteria'!$P$3:$Q$11),2,1) -> 0.02 | V62: Referral | W62: =VLOOKUP(F62,INDIRECT(V62&"!$A$1:$B$296"),2,0) -> 0.02 | X62: =_xlfn.XLOOKUP(F62,'Product List'!$B$1:$B$299,'Product List'!$A$1:$A$299) -> Xerox 212 | Z62: {=_xlfn.XLOOKUP(D62,'Customer Details'!$A$1:$A$17,'Customer Details'!$B$1:$F$17,"No such customer",0,1)} -> GHCL Ltd. | AA62: 58 Clarence St | AB62: Richmond | AC62: CA | AD62: 94805
... A1275: NUM000882 | B1275: 42367 | C1275: BHAGYASHRI | D1275: 10009 | E1275: =VLOOKUP($D1275,'Customer Details'!$A$1:$F$17,4,FALSE) -> Salt Lake City | F1275: P0151 | G1275: 2 | H1275: =VLOOKUP($D1275,'Customer Details'!$A$1:$F$17,MATCH('Order SUmmary'!H$2,'Customer Details'!$A$1:$F$1,0),0) -> Godfrey Philips India Ltd. | I1275: =VLOOKUP($D1275,'Customer Details'!$A$1:$F$17,4,0) -> Salt Lake City | J1275: =VLOOKUP($D1275,'Customer Details'!$A$1:$F$17,6,0) -> 84118 | K1275: =VLOOKUP(VLOOKUP(D1275,'Customer Details'!$A$1:$F$17,5,0),'Region INfo'!$A$1:$C$52,3,0) -> Pacific | L1275: =INDEX(Product_List,MATCH($F1275,'Product List'!$B$1:$B$299,0),MATCH('Order SUmmary'!L$2,'Product List'!$A$1:$E$1,0)) -> Xerox 1970 | M1275: =INDEX(Product_List,MATCH($F1275,'Product List'!$B$1:$B$299,0),MATCH('Order SUmmary'!M$2,'Product List'!$A$1:$E$1,0)) -> 3277 | N1275: =INDEX(Product_List,MATCH($F1275,'Product List'!$B$1:$B$299,0),MATCH('Order SUmmary'!N$2,'Product List'!$A$1:$E$1,0)) -> 1891 | O1275: =INDEX(Product_List,MATCH($F1275,'Product List'!$B$1:$B$299,0),MATCH('Order SUmmary'!O$2,'Product List'!$A$1:$E$1,0)) -> Paper | P1275: =HLOOKUP(C1275,'Commission Criteria'!$A$2:$I$4,3,FALSE) -> 1 | Q1275: =N1275*G1275 -> 3782 | R1275: =M1275*G1275 -> 6554 | S1275: =VLOOKUP(R1275,'Commission Criteria'!$L$3:$M$11,2,TRUE) -> 0.03 | T1275: =IF(P1275<5,VLOOKUP(R1275,'Commission Criteria'!$L$3:$M$11,2,1),VLOOKUP('Order SUmmary'!R1275,'Commission Criteria'!$P$3:$Q$11,2,1)) -> 0.03 | U1275: =VLOOKUP(R1275,IF(P1275<5,'Commission Criteria'!$L$3:$M$11,'Commission Criteria'!$P$3:$Q$11),2,1) -> 0.03 | V1275: India_mart | W1275: =VLOOKUP(F1275,INDIRECT(V1275&"!$A$1:$B$296"),2,0) -> 0.05 | X1275: =_xlfn.XLOOKUP(F1275,'Product List'!$B$1:$B$299,'Product List'!$A$1:$A$299) -> Xerox 1970 | Z1275: {=_xlfn.XLOOKUP(D1275,'Customer Details'!$A$1:$A$17,'Customer Details'!$B$1:$F$17,"No such customer",0,1)} -> Godfrey Philips India Ltd. | AA1275: 20501 Ania Ave #2 | AB1275: Salt Lake City | AC1275: UT | AD1275: 84118

Sheet Customer Details
A1: CustomerID | B1: Name | C1: Address | D1: City | E1: State | F1: Zip | H1: Region
A2: 10001 | B2: Chambal Fertilisers and Chemicals Ltd. | C2: 4951 Indiana Ave. | D2: New York | E2: NY | F2: 10025 | H2: =VLOOKUP($E2,'Region INfo'!$A$1:$C$52,3,FALSE) -> Northern
A3: 10002 | B3: Elder Pharmaceuticals | C3: 57 Neriba Cres | D3: Omaha | E3: NE | F3: 68127 | H3: =VLOOKUP($E3,'Region INfo'!$A$1:$C$52,3,FALSE) -> Western
A4: 10003 | B4: Honeywell Automation | C4: 1272 Harbor Road | D4: Miami | E4: FL | F4: 33732 | H4: =VLOOKUP($E4,'Region INfo'!$A$1:$C$52,3,FALSE) -> Southern
A5: 10004 | B5: Lupin Ltd. | C5: Abbey Wood | D5: New York | E5: NY | F5: 10019 | H5: =VLOOKUP($E5,'Region INfo'!$A$1:$C$52,3,FALSE) -> Northern
A6: 10005 | B6: Fortis Healthcare Ltd. | C6: 14 Elsworthy Terrace | D6: Goleta | E6: CA | F6: 93117 | H6: =VLOOKUP($E6,'Region INfo'!$A$1:$C$52,3,FALSE) -> Pacific
A7: 10006 | B7: Supreme Ind | C7: P.O. Box 1367 | D7: Midland | E7: TX | F7: 79706 | H7: =VLOOKUP($E7,'Region INfo'!$A$1:$C$52,3,FALSE) -> Western
A8: 10007 | B8: GHCL Ltd. | C8: 58 Clarence St | D8: Richmond | E8: CA | F8: 94805 | H8: =VLOOKUP($E8,'Region INfo'!$A$1:$C$52,3,FALSE) -> Pacific
A9: 10008 | B9: Reliance Industries Limited | C9: 12020 Shamrock Rd., Suite 333 | D9: Chestnut Ridge | E9: NY | F9: 10977 | H9: =VLOOKUP($E9,'Region INfo'!$A$1:$C$52,3,FALSE) -> Northern
A10: 10009 | B10: Godfrey Philips India Ltd. | C10: 20501 Ania Ave #2 | D10: Salt Lake City | E10: UT | F10: 84118 | H10: =VLOOKUP($E10,'Region INfo'!$A$1:$C$52,3,FALSE) -> Pacific
A11: 10010 | B11: Suzlon Energy Ltd. | C11: 501 Marsh Trail Circle | D11: Tracy | E11: CA | F11: 95376 | H11: =VLOOKUP($E11,'Region INfo'!$A$1:$C$52,3,FALSE) -> Pacific
A12: 10011 | B12: Sonata Software | C12: 1331 Kimberly Dr. | D12: Olympia | E12: WA | F12: 98502 | H12: =VLOOKUP($E12,'Region INfo'!$A$1:$C$52,3,FALSE) -> Pacific
A13: 10012 | B13: Dynamatic Technologies Ltd. | C13: 402 Pinkster Lane | D13: Santa Barbara | E13: CA | F13: 93110 | H13: =VLOOKUP($E13,'Region INfo'!$A$1:$C$52,3,FALSE) -> Pacific
... A17: 10016 | B17: Punj Lloyd Ltd. | C17: Box 3263 | D17: South Windsor | E17: CT | F17: 06074 | H17: =VLOOKUP($E17,'Region INfo'!$A$1:$C$52,3,FALSE) -> Northern

Sheet Region INfo
A1: State | B1: StateName | C1: Region
A2: AK | B2: Alaska | C2: Pacific
A3: AL | B3: Alabama | C3: Southern
A4: AR | B4: Arkansas | C4: Southern
A5: AZ | B5: Arizona | C5: Pacific
A6: CA | B6: California | C6: Pacific
A7: CO | B7: Colorado | C7: Western
A8: CT | B8: Connecticut | C8: Northern
A9: DC | B9: District of Columbia | C9: Northern
A10: DE | B10: Delaware | C10: Northern
A11: FL | B11: Florida | C11: Southern
A12: GA | B12: Georgia | C12: Southern
... A52: WY | B52: Wyoming | C52: Western

Sheet Match
A1: Sr.No | B1: Name
A2: 1 | B2: Chambal Fertilisers & Chemicals Ltd. | C2: 1
A3: 2 | B3: Elder Pharmaceuticals | C3: 2
A4: 3 | B4: Honeywell Automation | C4: 3
A5: 4 | B5: Lupin Ltd. | C5: 4 | D5: Enter Name | E5: Sonata Software
A6: 5 | B6: Fortis Healthcare Ltd. | C6: 5 | D6: Position is | E6: =MATCH(E5,$B$2:$B$16,0) -> 11
A7: 6 | B7: Supreme Industries
A8: 7 | B8: GHCL Ltd.
A9: 8 | B9: Reliance Industries Limited
A10: 9 | B10: Godfrey Philips India Ltd.
A11: 10 | B11: Suzlon Energy Ltd.
A12: 11 | B12: Sonata Software
A13: 12 | B13: Dynamatic Technologies Ltd.
A14: 13 | B14: GMR Infrastructure Ltd.
A15: 14 | B15: Hindusthan National Industries Ltd.
A16: 15 | B16: Punj Lloyd Ltd.
A19: Sr.No | B19: 1 | C19: 2 | D19: 3 | E19: 4
A20: Name | B20: Chambal Fertilisers & Chemicals Ltd. | C20: Elder Pharmaceuticals | D20: Honeywell Automation | E20: Lupin Ltd.
B23: Enter Name | C23: Lupin Ltd.
B24: Position is | C24: =MATCH(C23,B20:E20,0) -> 4
B29: Value1 | C29: Value2 | D29: Value3
A30: 1 | B30: 100 | C30: 400 | D30: 100 | E30: 1
A31: 2 | B31: 400 | C31: 300 | D31: 200 | E31: 2
A32: 3 | B32: 200 | C32: 200 | D32: 300 | E32: 3
A33: 4 | B33: 300 | C33: 100 | D33: 400 | E33: 4
A35: Enter Number | B35: 100 | C35: 150 | D35: 210
A36: Position is | B36: =MATCH(B35,B30:B33,0) -> 1 | C36: =MATCH(C35,C30:C33,-1) -> 3 | D36: =MATCH(D35,D30:D33,1) -> 2

Sheet Product List
A1: Product | B1: Product ID | C1: Product Category | D1: Price | E1: Cost
A2: Newell 322 | B2: P0001 | C2: Art | D2: 3472 | E2: 2239
A3: Xerox 1967 | B3: P0002 | C3: Paper | D3: 2552 | E3: 1905
A4: Newell 341 | B4: P0003 | C4: Art | D4: 2617 | E4: 1736 | G4: Simple Index | H4: =INDEX(Product_List,8,5) -> 2437 | I4: =IFERROR(_xlfn.FORMULATEXT(H4),"") -> =INDEX(Product_List,8,5)
A5: Newell 318 | B5: P0004 | C5: Art | D5: 4099 | E5: 1530 | G5: Enter Product ID | H5: P0005 | I5: =IFERROR(_xlfn.FORMULATEXT(H5),"")
A6: GE 30524EE4 | B6: P0005 | C6: Phones | D6: 2553 | E6: 1638 | G6: Get Row number of Entered Product ID | H6: P0016 | I6: =IFERROR(_xlfn.FORMULATEXT(H6),"")
A7: Avery 485 | B7: P0006 | C7: Labels | D7: 3060 | E7: 1258 | G7: Index with 1 Match | H7: =MATCH(H6,$B$1:$B$299,0) -> 17 | I7: =IFERROR(_xlfn.FORMULATEXT(H7),"") -> =MATCH(H6,$B$1:$B$299,0)
A8: Xerox 232 | B8: P0007 | C8: Paper | D8: 2814 | E8: 2437 | G8: Enter Column Name | H8: Cost
A9: Xerox 1943 | B9: P0008 | C9: Paper | D9: 2529 | E9: 1630 | G9: Get Column number of Entered Column Name | H9: =MATCH(H8,$A$1:$E$1,0) -> 5 | I9: =IFERROR(_xlfn.FORMULATEXT(H9),"") -> =MATCH(H8,$A$1:$E$1,0)
A10: Avery 511 | B10: P0009 | C10: Labels | D10: 4706 | E10: 1714 | G10: Index with 2 Match | H10: =INDEX(Product_List,MATCH(H6,$B$1:$B$299,0),MATCH(H8,$A$1:$E$1,0)) -> 1705 | I10: =IFERROR(_xlfn.FORMULATEXT(H10),"") -> =INDEX(Product_List,MATCH(H6,$B$1:$B$299,0),MATCH(H8,$A$1:$E$1,0))
A11: Xerox 1995 | B11: P0010 | C11: Paper | D11: 3454 | E11: 1525
A12: Xerox 1999 | B12: P0011 | C12: Paper | D12: 2612 | E12: 1994
A13: Xerox 1921 | B13: P0012 | C13: Paper | D13: 3150 | E13: 1218
A14: Xerox 1916 | B14: P0013 | C14: Paper | D14: 3499 | E14: 2342
A15: Staples | B15: P0014 | C15: Fasteners | D15: 2747 | E15: 2098
A16: Xerox 195 | B16: P0015 | C16: Paper | D16: 4531 | E16: 1566
A17: Xerox 1880 | B17: P0016 | C17: Paper | D17: 3642 | E17: 1705
A18: Ideal Clamps | B18: P0017 | C18: Fasteners | D18: 4459 | E18: 1722
A19: Newell 343 | B19: P0018 | C19: Art | D19: 2744 | E19: 1428
A20: Xerox 1911 | B20: P0019 | C20: Paper | D20: 4724 | E20: 2467
A21: Xerox 1883 | B21: P0020 | C21: Paper | D21: 3112 | E21: 1766
A22: Newell 311 | B22: P0021 | C22: Art | D22: 4689 | E22: 1796
... A299: LG G2 | B299: P0299 | C299: Phones | D299: 4305 | E299: 1703

Sheet Commission Criteria
L1: Commission Details<5 | P1: Commission Details>5
A2: Sales Person | B2: ASHWINI | C2: MEEHIR | D2: APOORVA | E2: BHAGYASHRI | F2: AJAY | G2: FARHIN | H2: NEHA | I2: NIKITA | L2: Sales Amount | M2: Commission % | P2: Sales Amount | Q2: Commission %
A3: Sales Person Id | B3: EMP10001 | C3: EMP10002 | D3: EMP10003 | E3: EMP10004 | F3: EMP10005 | G3: EMP10006 | H3: EMP10007 | I3: EMP10008 | L3: 0 | M3: 0.01 | P3: 0 | Q3: 0.02
A4: Year of Experience | B4: 4 | C4: 5 | D4: 8 | E4: 1 | F4: 10 | G4: 3 | H4: 6 | I4: 4 | L4: 5000 | M4: 0.03 | P4: 25000 | Q4: 0.04
L5: 25000 | M5: 0.05 | P5: 50000 | Q5: 0.06
L6: 75000 | M6: 0.07 | P6: 75000 | Q6: 0.08
L7: 100000 | M7: 0.09 | P7: 100000 | Q7: 0.1
L8: 120000 | M8: 0.11 | P8: 120000 | Q8: 0.12
L9: 150000 | M9: 0.13 | P9: 150000 | Q9: 0.14
L10: 175000 | M10: 0.15 | P10: 175000 | Q10: 0.16
L11: 200000 | M11: 0.17 | P11: 200000 | Q11: 0.18

Sheet Indirect
B3: Product_A | C3: Product_B | D3: Product_C | F3: {=Product_A} -> 100 | H3: {=INDIRECT(C10)} -> 10
B4: 100 | C4: 350 | D4: 10 | F4: 400 | H4: 20
B5: 400 | C5: 400 | D5: 20 | F5: 200 | H5: 0
B6: 200 | C6: 450 | F6: 300 | H6: 35
B7: 300 | C7: 500 | D7: 35
B10: Select the Product | C10: Product_C
B12: Sum is | C12: =IF(C10="Product_A",SUM($B$4:$B$7),IF(C10="Product_B",SUM(C4:C7),SUM(D4:D7))) -> 65 | D12: =IFERROR(_xlfn.FORMULATEXT(C12),"") -> =IF(C10="Product_A",SUM($B$4:$B$7),IF(C10="Product_B",SUM(C4:C7),SUM(D4:D7)))
B13: Average is | C13: =AVERAGE(IF(C10="Product_A",$B$4:$B$7,IF(C10="product_B",$C$4:$C$7,D4:D7))) -> 21.666667 | D13: =IFERROR(_xlfn.FORMULATEXT(C13),"") -> =AVERAGE(IF(C10="Product_A",$B$4:$B$7,IF(C10="product_B",$C$4:$C$7,D4:D7)))
B15: Sum is | C15: =SUM(INDIRECT(C10)) -> 65 | D15: =IFERROR(_xlfn.FORMULATEXT(C15),"") -> =SUM(INDIRECT(C10))
B16: Average is | C16: =AVERAGE(INDIRECT(C10)) -> 21.666667 | D16: =IFERROR(_xlfn.FORMULATEXT(C16),"") -> =AVERAGE(INDIRECT(C10))
B20: Sum is | C20: =IF(C10="Product_A",SUM(Product_A),IF(C10="Product_B",SUM(Product_B),SUM(Product_C))) -> 65 | D20: =IFERROR(_xlfn.FORMULATEXT(C20),"") -> =IF(C10="Product_A",SUM(Product_A),IF(C10="Product_B",SUM(Product_B),SUM(Product_C)))
B21: Average is | C21: =AVERAGE(IF(C10="Product_A",Product_A,IF(C10="Product_B",Product_B,Product_C))) -> 21.666667 | D21: =IFERROR(_xlfn.FORMULATEXT(C21),"") -> =AVERAGE(IF(C10="Product_A",Product_A,IF(C10="Product_B",Product_B,Product_C)))

Sheet Order Details
A1: OrderNum | B1: OrderDate | C1: Sales Person | D1: CustomerID | E1: ProductID | F1: Order Source | G1: Discount% with normal Vlookup | H1: Discount% with Indirect Vlookup | I1: Product Name by Xlookup | J1: Customer Name by Xlookup | K1: Address | L1: City | M1: State | N1: Zip
A2: NUM000001 | B2: 41282 | C2: ASHWINI | D2: 10011 | E2: P0210 | F2: Referral | G2: =VLOOKUP(E2,Flipkart!$A$1:$B$296,2,0) -> 0 | H2: =VLOOKUP(E2,INDIRECT(F2&"!$A$1:$B$296"),2,0) -> 0.01 | I2: =_xlfn.XLOOKUP(E2,'Product List'!$B$2:$B$299,'Product List'!$A$2:$A$299) -> Xerox 1951 | J2: {=_xlfn.XLOOKUP(D2,'Customer Details'!$A$1:$A$17,'Customer Details'!$B$1:$F$17,"No such customer",0,1)} -> Sonata Software | K2: 1331 Kimberly Dr. | L2: Olympia | M2: WA | N2: 98502
A3: NUM000002 | B3: 41283 | C3: ASHWINI | D3: 10007 | E3: P0134 | F3: India_mart | G3: =VLOOKUP(E3,Flipkart!$A$1:$B$296,2,0) -> 0.01 | H3: =VLOOKUP(E3,INDIRECT(F3&"!$A$1:$B$296"),2,0) -> 0.05 | I3: =_xlfn.XLOOKUP(E3,'Product List'!$B$2:$B$299,'Product List'!$A$2:$A$299) -> Avery 494
